Workbook

Sheet RawData
A1: 시행년도 | B1: 시행사 구분 | C1: 권역구 구분
A2: 2025 | B2: 신분당 | C2: 성남시
A5: 순번 | B5: 조사측선명 | C5: 손상구분번호 | D5: 침하(mm) | E5: 균열 | F5: 습윤 | G5: 노후도(년) | H5: 지반침하 발생 등의 이력(1년 이내) | I5: 침하 | J5: 균열 | K5: 습윤 | L5: 노후도 | M5: 보수보강이력 | N5: 평가점수 | O5: 평가등급 | P5: 조사자 의견 | Q5: 인접지번주소(도로명주소) | R5: 조사 위치도 | S5: 부가정보 1 | T5: 부가정보 2
A6: 1 | B6: 성남대로 | C6: =RIGHT($A$2,2)&"-"&$C$2&"-"&A6 -> 25-성남시-1 | D6: 양호 | E6: 종균열 횡균열 | F6: 건조 | G6: 9.3 | H6: - | I6: =IF(D6="양호",0,IF(D6="보통",3,IF(D6="긴급",9))) -> 0 | J6: =IF(E6="거북등",3,IF(RIGHT(E6,2)="균열",1,IF(E6="-",0))) -> 1 | K6: =IF(F6="유출",9,IF(F6="습윤",1,IF(F6="양호",0,IF(F6="건조",0)))) -> 0 | L6: =IF(G6<10,0,IF(G6<30,1,IF(G6>=30,2))) -> 0 | M6: =IF(H6="-",0,1) -> 0 | N6: =SUM(I6:M6) -> 1 | O6: =IF(N6<6,"일반",IF(N6<9,"우선",IF(N6>=9,"긴급"))) -> 일반 | S6: 하나은행 앞 반대도로
A7: 2 | B7: 성남대로 | C7: =RIGHT($A$2,2)&"-"&$C$2&"-"&A7 -> 25-성남시-2 | D7: 양호 | E7: 횡균열 | F7: 건조 | G7: 9.3 | H7: - | I7: =IF(D7="양호",0,IF(D7="보통",3,IF(D7="긴급",9))) -> 0 | J7: =IF(E7="거북등",3,IF(RIGHT(E7,2)="균열",1,IF(E7="-",0))) -> 1 | K7: =IF(F7="유출",9,IF(F7="습윤",1,IF(F7="양호",0,IF(F7="건조",0)))) -> 0 | L7: =IF(G7<10,0,IF(G7<30,1,IF(G7>=30,2))) -> 0 | M7: =IF(H7="-",0,1) -> 0 | N7: =SUM(I7:M7) -> 1 | O7: =IF(N7<6,"일반",IF(N7<9,"우선",IF(N7>=9,"긴급"))) -> 일반 | S7: 상록마을(임광/보성) 미켈란쉐르빌 앞 버스정류장
A8: 3 | B8: 성남대로 | C8: =RIGHT($A$2,2)&"-"&$C$2&"-"&A8 -> 25-성남시-3 | D8: 보통 | E8: - | F8: 건조 | G8: 9.3 | H8: - | I8: =IF(D8="양호",0,IF(D8="보통",3,IF(D8="긴급",9))) -> 3 | J8: =IF(E8="거북등",3,IF(RIGHT(E8,2)="균열",1,IF(E8="-",0))) -> 0 | K8: =IF(F8="유출",9,IF(F8="습윤",1,IF(F8="양호",0,IF(F8="건조",0)))) -> 0 | L8: =IF(G8<10,0,IF(G8<30,1,IF(G8>=30,2))) -> 0 | M8: =IF(H8="-",0,1) -> 0 | N8: =SUM(I8:M8) -> 3 | O8: =IF(N8<6,"일반",IF(N8<9,"우선",IF(N8>=9,"긴급"))) -> 일반 | P8: 보도침하 8cm | S8: 미켈란쉐르빌 B동 앞 맞음편 보도
A9: 4 | B9: 성남대로 | C9: =RIGHT($A$2,2)&"-"&$C$2&"-"&A9 -> 25-성남시-4 | D9: 양호 | E9: 거북등 | F9: 건조 | G9: 9.3 | H9: - | I9: =IF(D9="양호",0,IF(D9="보통",3,IF(D9="긴급",9))) -> 0 | J9: =IF(E9="거북등",3,IF(RIGHT(E9,2)="균열",1,IF(E9="-",0))) -> 3 | K9: =IF(F9="유출",9,IF(F9="습윤",1,IF(F9="양호",0,IF(F9="건조",0)))) -> 0 | L9: =IF(G9<10,0,IF(G9<30,1,IF(G9>=30,2))) -> 0 | M9: =IF(H9="-",0,1) -> 0 | N9: =SUM(I9:M9) -> 3 | O9: =IF(N9<6,"일반",IF(N9<9,"우선",IF(N9>=9,"긴급"))) -> 일반 | S9: 야생화지하보도 양차선도로
A10: 5 | B10: 성남대로 | C10: =RIGHT($A$2,2)&"-"&$C$2&"-"&A10 -> 25-성남시-5 | D10: 양호 | E10: 거북등 | F10: 건조 | G10: 9.3 | H10: - | I10: =IF(D10="양호",0,IF(D10="보통",3,IF(D10="긴급",9))) -> 0 | J10: =IF(E10="거북등",3,IF(RIGHT(E10,2)="균열",1,IF(E10="-",0))) -> 3 | K10: =IF(F10="유출",9,IF(F10="습윤",1,IF(F10="양호",0,IF(F10="건조",0)))) -> 0 | L10: =IF(G10<10,0,IF(G10<30,1,IF(G10>=30,2))) -> 0 | M10: =IF(H10="-",0,1) -> 0 | N10: =SUM(I10:M10) -> 3 | O10: =IF(N10<6,"일반",IF(N10<9,"우선",IF(N10>=9,"긴급"))) -> 일반 | S10: 상록마을 버스정류장 앞 양차선도로
A11: 6 | B11: 성남대로 | C11: =RIGHT($A$2,2)&"-"&$C$2&"-"&A11 -> 25-성남시-6 | D11: 양호 | E11: 거북등 | F11: 건조 | G11: 9.3 | H11: - | I11: =IF(D11="양호",0,IF(D11="보통",3,IF(D11="긴급",9))) -> 0 | J11: =IF(E11="거북등",3,IF(RIGHT(E11,2)="균열",1,IF(E11="-",0))) -> 3 | K11: =IF(F11="유출",9,IF(F11="습윤",1,IF(F11="양호",0,IF(F11="건조",0)))) -> 0 | L11: =IF(G11<10,0,IF(G11<30,1,IF(G11>=30,2))) -> 0 | M11: =IF(H11="-",0,1) -> 0 | N11: =SUM(I11:M11) -> 3 | O11: =IF(N11<6,"일반",IF(N11<9,"우선",IF(N11>=9,"긴급"))) -> 일반 | S11: 금곡사거리 도로
A12: 7 | B12: 성남대로 | C12: =RIGHT($A$2,2)&"-"&$C$2&"-"&A12 -> 25-성남시-7 | D12: 양호 | E12: 횡균열 | F12: 건조 | G12: 9.3 | H12: - | I12: =IF(D12="양호",0,IF(D12="보통",3,IF(D12="긴급",9))) -> 0 | J12: =IF(E12="거북등",3,IF(RIGHT(E12,2)="균열",1,IF(E12="-",0))) -> 1 | K12: =IF(F12="유출",9,IF(F12="습윤",1,IF(F12="양호",0,IF(F12="건조",0)))) -> 0 | L12: =IF(G12<10,0,IF(G12<30,1,IF(G12>=30,2))) -> 0 | M12: =IF(H12="-",0,1) -> 0 | N12: =SUM(I12:M12) -> 1 | O12: =IF(N12<6,"일반",IF(N12<9,"우선",IF(N12>=9,"긴급"))) -> 일반 | S12: 분당경영고등학교 앞 도로
A13: 8 | B13: 성남대로 | C13: =RIGHT($A$2,2)&"-"&$C$2&"-"&A13 -> 25-성남시-8 | D13: 양호 | E13: 거북등 | F13: 건조 | G13: 9.3 | H13: - | I13: =IF(D13="양호",0,IF(D13="보통",3,IF(D13="긴급",9))) -> 0 | J13: =IF(E13="거북등",3,IF(RIGHT(E13,2)="균열",1,IF(E13="-",0))) -> 3 | K13: =IF(F13="유출",9,IF(F13="습윤",1,IF(F13="양호",0,IF(F13="건조",0)))) -> 0 | L13: =IF(G13<10,0,IF(G13<30,1,IF(G13>=30,2))) -> 0 | M13: =IF(H13="-",0,1) -> 0 | N13: =SUM(I13:M13) -> 3 | O13: =IF(N13<6,"일반",IF(N13<9,"우선",IF(N13>=9,"긴급"))) -> 일반 | P13: 5cm미만 침하 | S13: #연결선 환기구 앞 도로
A14: 9 | B14: 성남대로 | C14: =RIGHT($A$2,2)&"-"&$C$2&"-"&A14 -> 25-성남시-9 | D14: 양호 | E14: 거북등 | F14: 건조 | G14: 9.3 | H14: - | I14: =IF(D14="양호",0,IF(D14="보통",3,IF(D14="긴급",9))) -> 0 | J14: =IF(E14="거북등",3,IF(RIGHT(E14,2)="균열",1,IF(E14="-",0))) -> 3 | K14: =IF(F14="유출",9,IF(F14="습윤",1,IF(F14="양호",0,IF(F14="건조",0)))) -> 0 | L14: =IF(G14<10,0,IF(G14<30,1,IF(G14>=30,2))) -> 0 | M14: =IF(H14="-",0,1) -> 0 | N14: =SUM(I14:M14) -> 3 | O14: =IF(N14<6,"일반",IF(N14<9,"우선",IF(N14>=9,"긴급"))) -> 일반 | S14: 청솔주공6단지 버스정류장 앞 도로
A15: 10 | B15: 성남대로 | C15: =RIGHT($A$2,2)&"-"&$C$2&"-"&A15 -> 25-성남시-10 | D15: 양호 | E15: 거북등 | F15: 건조 | G15: 9.3 | H15: - | I15: =IF(D15="양호",0,IF(D15="보통",3,IF(D15="긴급",9))) -> 0 | J15: =IF(E15="거북등",3,IF(RIGHT(E15,2)="균열",1,IF(E15="-",0))) -> 3 | K15: =IF(F15="유출",9,IF(F15="습윤",1,IF(F15="양호",0,IF(F15="건조",0)))) -> 0 | L15: =IF(G15<10,0,IF(G15<30,1,IF(G15>=30,2))) -> 0 | M15: =IF(H15="-",0,1) -> 0 | N15: =SUM(I15:M15) -> 3 | O15: =IF(N15<6,"일반",IF(N15<9,"우선",IF(N15>=9,"긴급"))) -> 일반 | S15: 청솔마을 사거리 앞 도로
A16: 11 | B16: 성남대로 | C16: =RIGHT($A$2,2)&"-"&$C$2&"-"&A16 -> 25-성남시-11 | D16: 양호 | E16: 거북등 | F16: 건조 | G16: 9.3 | H16: - | I16: =IF(D16="양호",0,IF(D16="보통",3,IF(D16="긴급",9))) -> 0 | J16: =IF(E16="거북등",3,IF(RIGHT(E16,2)="균열",1,IF(E16="-",0))) -> 3 | K16: =IF(F16="유출",9,IF(F16="습윤",1,IF(F16="양호",0,IF(F16="건조",0)))) -> 0 | L16: =IF(G16<10,0,IF(G16<30,1,IF(G16>=30,2))) -> 0 | M16: =IF(H16="-",0,1) -> 0 | N16: =SUM(I16:M16) -> 3 | O16: =IF(N16<6,"일반",IF(N16<9,"우선",IF(N16>=9,"긴급"))) -> 일반 | S16: 청솔마을성원7단지 아파트707동 도로
A17: 12 | B17: 성남대로 | C17: =RIGHT($A$2,2)&"-"&$C$2&"-"&A17 -> 25-성남시-12 | D17: 양호 | E17: 횡균열 | F17: 건조 | G17: 9.3 | H17: - | I17: =IF(D17="양호",0,IF(D17="보통",3,IF(D17="긴급",9))) -> 0 | J17: =IF(E17="거북등",3,IF(RIGHT(E17,2)="균열",1,IF(E17="-",0))) -> 1 | K17: =IF(F17="유출",9,IF(F17="습윤",1,IF(F17="양호",0,IF(F17="건조",0)))) -> 0 | L17: =IF(G17<10,0,IF(G17<30,1,IF(G17>=30,2))) -> 0 | M17: =IF(H17="-",0,1) -> 0 | N17: =SUM(I17:M17) -> 1 | O17: =IF(N17<6,"일반",IF(N17<9,"우선",IF(N17>=9,"긴급"))) -> 일반 | S17: 청솔마을성원7단지 아파트706동 도로
A18: 13 | B18: 성남대로 | C18: =RIGHT($A$2,2)&"-"&$C$2&"-"&A18 -> 25-성남시-13 | D18: 양호 | E18: 거북등 | F18: 건조 | G18: 9.3 | H18: - | I18: =IF(D18="양호",0,IF(D18="보통",3,IF(D18="긴급",9))) -> 0 | J18: =IF(E18="거북등",3,IF(RIGHT(E18,2)="균열",1,IF(E18="-",0))) -> 3 | K18: =IF(F18="유출",9,IF(F18="습윤",1,IF(F18="양호",0,IF(F18="건조",0)))) -> 0 | L18: =IF(G18<10,0,IF(G18<30,1,IF(G18>=30,2))) -> 0 | M18: =IF(H18="-",0,1) -> 0 | N18: =SUM(I18:M18) -> 3 | O18: =IF(N18<6,"일반",IF(N18<9,"우선",IF(N18>=9,"긴급"))) -> 일반 | S18: 청솔마을 서광영남아파트103동 앞 도로
A19: 14 | B19: 성남대로 | C19: =RIGHT($A$2,2)&"-"&$C$2&"-"&A19 -> 25-성남시-14 | D19: 양호 | E19: 거북등 | F19: 건조 | G19: 9.3 | H19: - | I19: =IF(D19="양호",0,IF(D19="보통",3,IF(D19="긴급",9))) -> 0 | J19: =IF(E19="거북등",3,IF(RIGHT(E19,2)="균열",1,IF(E19="-",0))) -> 3 | K19: =IF(F19="유출",9,IF(F19="습윤",1,IF(F19="양호",0,IF(F19="건조",0)))) -> 0 | L19: =IF(G19<10,0,IF(G19<30,1,IF(G19>=30,2))) -> 0 | M19: =IF(H19="-",0,1) -> 0 | N19: =SUM(I19:M19) -> 3 | O19: =IF(N19<6,"일반",IF(N19<9,"우선",IF(N19>=9,"긴급"))) -> 일반 | S19: GS25 분당성원점 앞 횡단보도
A20: 15 | B20: 성남대로 | C20: =RIGHT($A$2,2)&"-"&$C$2&"-"&A20 -> 25-성남시-15 | D20: 양호 | E20: 종균열 | F20: 건조 | G20: 9.3 | H20: - | I20: =IF(D20="양호",0,IF(D20="보통",3,IF(D20="긴급",9))) -> 0 | J20: =IF(E20="거북등",3,IF(RIGHT(E20,2)="균열",1,IF(E20="-",0))) -> 1 | K20: =IF(F20="유출",9,IF(F20="습윤",1,IF(F20="양호",0,IF(F20="건조",0)))) -> 0 | L20: =IF(G20<10,0,IF(G20<30,1,IF(G20>=30,2))) -> 0 | M20: =IF(H20="-",0,1) -> 0 | N20: =SUM(I20:M20) -> 1 | O20: =IF(N20<6,"일반",IF(N20<9,"우선",IF(N20>=9,"긴급"))) -> 일반 | S20: 옥된장 앞 도로
A21: 16 | B21: 성남대로 | C21: =RIGHT($A$2,2)&"-"&$C$2&"-"&A21 -> 25-성남시-16 | D21: 양호 | E21: 거북등 | F21: 건조 | G21: 9.3 | H21: - | I21: =IF(D21="양호",0,IF(D21="보통",3,IF(D21="긴급",9))) -> 0 | J21: =IF(E21="거북등",3,IF(RIGHT(E21,2)="균열",1,IF(E21="-",0))) -> 3 | K21: =IF(F21="유출",9,IF(F21="습윤",1,IF(F21="양호",0,IF(F21="건조",0)))) -> 0 | L21: =IF(G21<10,0,IF(G21<30,1,IF(G21>=30,2))) -> 0 | M21: =IF(H21="-",0,1) -> 0 | N21: =SUM(I21:M21) -> 3 | O21: =IF(N21<6,"일반",IF(N21<9,"우선",IF(N21>=9,"긴급"))) -> 일반 | S21: 올리브영 앞 도로
A22: 17 | B22: 성남대로 | C22: =RIGHT($A$2,2)&"-"&$C$2&"-"&A22 -> 25-성남시-17 | D22: 양호 | E22: 거북등 | F22: 건조 | G22: 9.3 | H22: - | I22: =IF(D22="양호",0,IF(D22="보통",3,IF(D22="긴급",9))) -> 0 | J22: =IF(E22="거북등",3,IF(RIGHT(E22,2)="균열",1,IF(E22="-",0))) -> 3 | K22: =IF(F22="유출",9,IF(F22="습윤",1,IF(F22="양호",0,IF(F22="건조",0)))) -> 0 | L22: =IF(G22<10,0,IF(G22<30,1,IF(G22>=30,2))) -> 0 | M22: =IF(H22="-",0,1) -> 0 | N22: =SUM(I22:M22) -> 3 | O22: =IF(N22<6,"일반",IF(N22<9,"우선",IF(N22>=9,"긴급"))) -> 일반 | S22: 미금역 버스정류장 앞 도로
A23: 18 | B23: 성남대로 | C23: =RIGHT($A$2,2)&"-"&$C$2&"-"&A23 -> 25-성남시-18 | D23: 양호 | E23: 거북등 | F23: 건조 | G23: 9.3 | H23: - | I23: =IF(D23="양호",0,IF(D23="보통",3,IF(D23="긴급",9))) -> 0 | J23: =IF(E23="거북등",3,IF(RIGHT(E23,2)="균열",1,IF(E23="-",0))) -> 3 | K23: =IF(F23="유출",9,IF(F23="습윤",1,IF(F23="양호",0,IF(F23="건조",0)))) -> 0 | L23: =IF(G23<10,0,IF(G23<30,1,IF(G23>=30,2))) -> 0 | M23: =IF(H23="-",0,1) -> 0 | N23: =SUM(I23:M23) -> 3 | O23: =IF(N23<6,"일반",IF(N23<9,"우선",IF(N23>=9,"긴급"))) -> 일반 | S23: 미금역 #1번출구 앞 도로
A24: 19 | B24: 성남대로 | C24: =RIGHT($A$2,2)&"-"&$C$2&"-"&A24 -> 25-성남시-19 | D24: 양호 | E24: 거북등 | F24: 건조 | G24: 9.3 | H24: - | I24: =IF(D24="양호",0,IF(D24="보통",3,IF(D24="긴급",9))) -> 0 | J24: =IF(E24="거북등",3,IF(RIGHT(E24,2)="균열",1,IF(E24="-",0))) -> 3 | K24: =IF(F24="유출",9,IF(F24="습윤",1,IF(F24="양호",0,IF(F24="건조",0)))) -> 0 | L24: =IF(G24<10,0,IF(G24<30,1,IF(G24>=30,2))) -> 0 | M24: =IF(H24="-",0,1) -> 0 | N24: =SUM(I24:M24) -> 3 | O24: =IF(N24<6,"일반",IF(N24<9,"우선",IF(N24>=9,"긴급"))) -> 일반 | S24: 미금역 교차로 도로
A25: 20 | B25: 성남대로 | C25: =RIGHT($A$2,2)&"-"&$C$2&"-"&A25 -> 25-성남시-20 | D25: 보통 | E25: 횡균열 | F25: 건조 | G25: 9.3 | H25: - | I25: =IF(D25="양호",0,IF(D25="보통",3,IF(D25="긴급",9))) -> 3 | J25: =IF(E25="거북등",3,IF(RIGHT(E25,2)="균열",1,IF(E25="-",0))) -> 1 | K25: =IF(F25="유출",9,IF(F25="습윤",1,IF(F25="양호",0,IF(F25="건조",0)))) -> 0 | L25: =IF(G25<10,0,IF(G25<30,1,IF(G25>=30,2))) -> 0 | M25: =IF(H25="-",0,1) -> 0 | N25: =SUM(I25:M25) -> 4 | O25: =IF(N25<6,"일반",IF(N25<9,"우선",IF(N25>=9,"긴급"))) -> 일반 | P25: 침하 5cm | S25: 미금역 #2번출구 앞 도로
A26: 21 | B26: 성남대로 | C26: =RIGHT($A$2,2)&"-"&$C$2&"-"&A26 -> 25-성남시-21 | D26: 양호 | E26: 거북등 | F26: 건조 | G26: 9.3 | H26: - | I26: =IF(D26="양호",0,IF(D26="보통",3,IF(D26="긴급",9))) -> 0 | J26: =IF(E26="거북등",3,IF(RIGHT(E26,2)="균열",1,IF(E26="-",0))) -> 3 | K26: =IF(F26="유출",9,IF(F26="습윤",1,IF(F26="양호",0,IF(F26="건조",0)))) -> 0 | L26: =IF(G26<10,0,IF(G26<30,1,IF(G26>=30,2))) -> 0 | M26: =IF(H26="-",0,1) -> 0 | N26: =SUM(I26:M26) -> 3 | O26: =IF(N26<6,"일반",IF(N26<9,"우선",IF(N26>=9,"긴급"))) -> 일반 | S26: 미금역 교차로 도로
A27: 22 | B27: 성남대로 | C27: =RIGHT($A$2,2)&"-"&$C$2&"-"&A27 -> 25-성남시-22 | D27: 양호 | E27: - | F27: 건조 | G27: 9.3 | H27: - | I27: =IF(D27="양호",0,IF(D27="보통",3,IF(D27="긴급",9))) -> 0 | J27: =IF(E27="거북등",3,IF(RIGHT(E27,2)="균열",1,IF(E27="-",0))) -> 0 | K27: =IF(F27="유출",9,IF(F27="습윤",1,IF(F27="양호",0,IF(F27="건조",0)))) -> 0 | L27: =IF(G27<10,0,IF(G27<30,1,IF(G27>=30,2))) -> 0 | M27: =IF(H27="-",0,1) -> 0 | N27: =SUM(I27:M27) -> 0 | O27: =IF(N27<6,"일반",IF(N27<9,"우선",IF(N27>=9,"긴급"))) -> 일반 | P27: 침하 3cm | S27: 미금역 #5출구 앞 도로
A28: 23 | B28: 성남대로 | C28: =RIGHT($A$2,2)&"-"&$C$2&"-"&A28 -> 25-성남시-23 | D28: 양호 | E28: 거북등 | F28: 건조 | G28: 9.3 | H28: - | I28: =IF(D28="양호",0,IF(D28="보통",3,IF(D28="긴급",9))) -> 0 | J28: =IF(E28="거북등",3,IF(RIGHT(E28,2)="균열",1,IF(E28="-",0))) -> 3 | K28: =IF(F28="유출",9,IF(F28="습윤",1,IF(F28="양호",0,IF(F28="건조",0)))) -> 0 | L28: =IF(G28<10,0,IF(G28<30,1,IF(G28>=30,2))) -> 0 | M28: =IF(H28="-",0,1) -> 0 | N28: =SUM(I28:M28) -> 3 | O28: =IF(N28<6,"일반",IF(N28<9,"우선",IF(N28>=9,"긴급"))) -> 일반 | P28: 5cm미만 침하 | S28: 미금역 피난계단 앞 도로
A29: 24 | B29: 성남대로 | C29: =RIGHT($A$2,2)&"-"&$C$2&"-"&A29 -> 25-성남시-24 | D29: 양호 | E29: 거북등 | F29: 건조 | G29: 9.3 | H29: - | I29: =IF(D29="양호",0,IF(D29="보통",3,IF(D29="긴급",9))) -> 0 | J29: =IF(E29="거북등",3,IF(RIGHT(E29,2)="균열",1,IF(E29="-",0))) -> 3 | K29: =IF(F29="유출",9,IF(F29="습윤",1,IF(F29="양호",0,IF(F29="건조",0)))) -> 0 | L29: =IF(G29<10,0,IF(G29<30,1,IF(G29>=30,2))) -> 0 | M29: =IF(H29="-",0,1) -> 0 | N29: =SUM(I29:M29) -> 3 | O29: =IF(N29<6,"일반",IF(N29<9,"우선",IF(N29>=9,"긴급"))) -> 일반 | S29: 나무수커피 앞 도로
A30: 25 | B30: 성남대로 | C30: =RIGHT($A$2,2)&"-"&$C$2&"-"&A30 -> 25-성남시-25 | D30: 양호 | E30: - | F30: 건조 | G30: 9.3 | H30: - | I30: =IF(D30="양호",0,IF(D30="보통",3,IF(D30="긴급",9))) -> 0 | J30: =IF(E30="거북등",3,IF(RIGHT(E30,2)="균열",1,IF(E30="-",0))) -> 0 | K30: =IF(F30="유출",9,IF(F30="습윤",1,IF(F30="양호",0,IF(F30="건조",0)))) -> 0 | L30: =IF(G30<10,0,IF(G30<30,1,IF(G30>=30,2))) -> 0 | M30: =IF(H30="-",0,1) -> 0 | N30: =SUM(I30:M30) -> 0 | O30: =IF(N30<6,"일반",IF(N30<9,"우선",IF(N30>=9,"긴급"))) -> 일반 | P30: 침하 4cm | S30: 택시승강장 앞 도로
A31: 26 | B31: 성남대로 | C31: =RIGHT($A$2,2)&"-"&$C$2&"-"&A31 -> 25-성남시-26 | D31: 양호 | E31: 거북등 | F31: 건조 | G31: 9.3 | H31: - | I31: =IF(D31="양호",0,IF(D31="보통",3,IF(D31="긴급",9))) -> 0 | J31: =IF(E31="거북등",3,IF(RIGHT(E31,2)="균열",1,IF(E31="-",0))) -> 3 | K31: =IF(F31="유출",9,IF(F31="습윤",1,IF(F31="양호",0,IF(F31="건조",0)))) -> 0 | L31: =IF(G31<10,0,IF(G31<30,1,IF(G31>=30,2))) -> 0 | M31: =IF(H31="-",0,1) -> 0 | N31: =SUM(I31:M31) -> 3 | O31: =IF(N31<6,"일반",IF(N31<9,"우선",IF(N31>=9,"긴급"))) -> 일반 | P31: 5cm미만 침하 | S31: 성남고용복지 플러스센터 앞 도로
A32: 27 | B32: 성남대로 | C32: =RIGHT($A$2,2)&"-"&$C$2&"-"&A32 -> 25-성남시-27 | D32: 양호 | E32: 거북등 | F32: 건조 | G32: 9.3 | H32: - | I32: =IF(D32="양호",0,IF(D32="보통",3,IF(D32="긴급",9))) -> 0 | J32: =IF(E32="거북등",3,IF(RIGHT(E32,2)="균열",1,IF(E32="-",0))) -> 3 | K32: =IF(F32="유출",9,IF(F32="습윤",1,IF(F32="양호",0,IF(F32="건조",0)))) -> 0 | L32: =IF(G32<10,0,IF(G32<30,1,IF(G32>=30,2))) -> 0 | M32: =IF(H32="-",0,1) -> 0 | N32: =SUM(I32:M32) -> 3 | O32: =IF(N32<6,"일반",IF(N32<9,"우선",IF(N32>=9,"긴급"))) -> 일반 | S32: 까치마을 건영빌라 503동 앞 도로
A33: 28 | B33: 성남대로 | C33: =RIGHT($A$2,2)&"-"&$C$2&"-"&A33 -> 25-성남시-28 | D33: 양호 | E33: 거북등 | F33: 건조 | G33: 9.3 | H33: - | I33: =IF(D33="양호",0,IF(D33="보통",3,IF(D33="긴급",9))) -> 0 | J33: =IF(E33="거북등",3,IF(RIGHT(E33,2)="균열",1,IF(E33="-",0))) -> 3 | K33: =IF(F33="유출",9,IF(F33="습윤",1,IF(F33="양호",0,IF(F33="건조",0)))) -> 0 | L33: =IF(G33<10,0,IF(G33<30,1,IF(G33>=30,2))) -> 0 | M33: =IF(H33="-",0,1) -> 0 | N33: =SUM(I33:M33) -> 3 | O33: =IF(N33<6,"일반",IF(N33<9,"우선",IF(N33>=9,"긴급"))) -> 일반 | P33: 5cm미만 침하 | S33: 까치마을 건영빌라 303동 앞 도로
A34: 29 | B34: 성남대로 | C34: =RIGHT($A$2,2)&"-"&$C$2&"-"&A34 -> 25-성남시-29 | D34: 양호 | E34: 양호 | F34: 건조 | G34: 9.3 | H34: - | I34: =IF(D34="양호",0,IF(D34="보통",3,IF(D34="긴급",9))) -> 0 | J34: =IF(E34="거북등",3,IF(RIGHT(E34,2)="균열",1,IF(E34="-",0))) -> FALSE | K34: =IF(F34="유출",9,IF(F34="습윤",1,IF(F34="양호",0,IF(F34="건조",0)))) -> 0 | L34: =IF(G34<10,0,IF(G34<30,1,IF(G34>=30,2))) -> 0 | M34: =IF(H34="-",0,1) -> 0 | N34: =SUM(I34:M34) -> 0 | O34: =IF(N34<6,"일반",IF(N34<9,"우선",IF(N34>=9,"긴급"))) -> 일반 | P34: 5cm미만 침하 | S34: 까치마을 건영빌라 302동 앞 도로
A35: 30 | B35: 성남대로 | C35: =RIGHT($A$2,2)&"-"&$C$2&"-"&A35 -> 25-성남시-30 | D35: 양호 | E35: 횡균열 | F35: 건조 | G35: 9.3 | H35: - | I35: =IF(D35="양호",0,IF(D35="보통",3,IF(D35="긴급",9))) -> 0 | J35: =IF(E35="거북등",3,IF(RIGHT(E35,2)="균열",1,IF(E35="-",0))) -> 1 | K35: =IF(F35="유출",9,IF(F35="습윤",1,IF(F35="양호",0,IF(F35="건조",0)))) -> 0 | L35: =IF(G35<10,0,IF(G35<30,1,IF(G35>=30,2))) -> 0 | M35: =IF(H35="-",0,1) -> 0 | N35: =SUM(I35:M35) -> 1 | O35: =IF(N35<6,"일반",IF(N35<9,"우선",IF(N35>=9,"긴급"))) -> 일반 | S35: 까치마을 지하보도 도로
A36: 31 | B36: 성남대로 | C36: =RIGHT($A$2,2)&"-"&$C$2&"-"&A36 -> 25-성남시-31 | D36: 양호 | E36: - | F36: 건조 | G36: 9.3 | H36: - | I36: =IF(D36="양호",0,IF(D36="보통",3,IF(D36="긴급",9))) -> 0 | J36: =IF(E36="거북등",3,IF(RIGHT(E36,2)="균열",1,IF(E36="-",0))) -> 0 | K36: =IF(F36="유출",9,IF(F36="습윤",1,IF(F36="양호",0,IF(F36="건조",0)))) -> 0 | L36: =IF(G36<10,0,IF(G36<30,1,IF(G36>=30,2))) -> 0 | M36: =IF(H36="-",0,1) -> 0 | N36: =SUM(I36:M36) -> 0 | O36: =IF(N36<6,"일반",IF(N36<9,"우선",IF(N36>=9,"긴급"))) -> 일반 | P36: 침하 2cm | S36: 까치마을 건영빌라 603동 앞 도로
A37: 32 | B37: 성남대로 | C37: =RIGHT($A$2,2)&"-"&$C$2&"-"&A37 -> 25-성남시-32 | D37: 양호 | E37: 거북등 | F37: 건조 | G37: 9.3 | H37: - | I37: =IF(D37="양호",0,IF(D37="보통",3,IF(D37="긴급",9))) -> 0 | J37: =IF(E37="거북등",3,IF(RIGHT(E37,2)="균열",1,IF(E37="-",0))) -> 3 | K37: =IF(F37="유출",9,IF(F37="습윤",1,IF(F37="양호",0,IF(F37="건조",0)))) -> 0 | L37: =IF(G37<10,0,IF(G37<30,1,IF(G37>=30,2))) -> 0 | M37: =IF(H37="-",0,1) -> 0 | N37: =SUM(I37:M37) -> 3 | O37: =IF(N37<6,"일반",IF(N37<9,"우선",IF(N37>=9,"긴급"))) -> 일반 | S37: 미금사거리 도로
A38: 33 | B38: 성남대로 | C38: =RIGHT($A$2,2)&"-"&$C$2&"-"&A38 -> 25-성남시-33 | D38: 양호 | E38: 거북등 | F38: 건조 | G38: 9.3 | H38: - | I38: =IF(D38="양호",0,IF(D38="보통",3,IF(D38="긴급",9))) -> 0 | J38: =IF(E38="거북등",3,IF(RIGHT(E38,2)="균열",1,IF(E38="-",0))) -> 3 | K38: =IF(F38="유출",9,IF(F38="습윤",1,IF(F38="양호",0,IF(F38="건조",0)))) -> 0 | L38: =IF(G38<10,0,IF(G38<30,1,IF(G38>=30,2))) -> 0 | M38: =IF(H38="-",0,1) -> 0 | N38: =SUM(I38:M38) -> 3 | O38: =IF(N38<6,"일반",IF(N38<9,"우선",IF(N38>=9,"긴급"))) -> 일반 | S38: 성남구미도서관 앞 도로
A39: 34 | B39: 성남대로 | C39: =RIGHT($A$2,2)&"-"&$C$2&"-"&A39 -> 25-성남시-34 | D39: 양호 | E39: 거북등 | F39: 건조 | G39: 9.3 | H39: - | I39: =IF(D39="양호",0,IF(D39="보통",3,IF(D39="긴급",9))) -> 0 | J39: =IF(E39="거북등",3,IF(RIGHT(E39,2)="균열",1,IF(E39="-",0))) -> 3 | K39: =IF(F39="유출",9,IF(F39="습윤",1,IF(F39="양호",0,IF(F39="건조",0)))) -> 0 | L39: =IF(G39<10,0,IF(G39<30,1,IF(G39>=30,2))) -> 0 | M39: =IF(H39="-",0,1) -> 0 | N39: =SUM(I39:M39) -> 3 | O39: =IF(N39<6,"일반",IF(N39<9,"우선",IF(N39>=9,"긴급"))) -> 일반 | P39: 5cm미만 침하 | S39: 서울그린빌 1동 앞 도로
A40: 35 | B40: 탄천상로 | C40: =RIGHT($A$2,2)&"-"&$C$2&"-"&A40 -> 25-성남시-35 | D40: 양호 | E40: 거북등 | F40: 건조 | G40: 9.3 | H40: - | I40: =IF(D40="양호",0,IF(D40="보통",3,IF(D40="긴급",9))) -> 0 | J40: =IF(E40="거북등",3,IF(RIGHT(E40,2)="균열",1,IF(E40="-",0))) -> 3 | K40: =IF(F40="유출",9,IF(F40="습윤",1,IF(F40="양호",0,IF(F40="건조",0)))) -> 0 | L40: =IF(G40<10,0,IF(G40<30,1,IF(G40>=30,2))) -> 0 | M40: =IF(H40="-",0,1) -> 0 | N40: =SUM(I40:M40) -> 3 | O40: =IF(N40<6,"일반",IF(N40<9,"우선",IF(N40>=9,"긴급"))) -> 일반 | S40: 동막교 앞 사거리 도로
A41: 36 | B41: 탄천상로 | C41: =RIGHT($A$2,2)&"-"&$C$2&"-"&A41 -> 25-성남시-36 | D41: 양호 | E41: 거북등 | F41: 건조 | G41: 9.3 | H41: - | I41: =IF(D41="양호",0,IF(D41="보통",3,IF(D41="긴급",9))) -> 0 | J41: =IF(E41="거북등",3,IF(RIGHT(E41,2)="균열",1,IF(E41="-",0))) -> 3 | K41: =IF(F41="유출",9,IF(F41="습윤",1,IF(F41="양호",0,IF(F41="건조",0)))) -> 0 | L41: =IF(G41<10,0,IF(G41<30,1,IF(G41>=30,2))) -> 0 | M41: =IF(H41="-",0,1) -> 0 | N41: =SUM(I41:M41) -> 3 | O41: =IF(N41<6,"일반",IF(N41<9,"우선",IF(N41>=9,"긴급"))) -> 일반 | S41: KD운송그룹 분당영업소 앞 도로
A42: 37 | B42: 분당수서로 | C42: =RIGHT($A$2,2)&"-"&$C$2&"-"&A42 -> 25-성남시-37 | D42: 양호 | E42: 거북등 | F42: 건조 | G42: 9.3 | H42: - | I42: =IF(D42="양호",0,IF(D42="보통",3,IF(D42="긴급",9))) -> 0 | J42: =IF(E42="거북등",3,IF(RIGHT(E42,2)="균열",1,IF(E42="-",0))) -> 3 | K42: =IF(F42="유출",9,IF(F42="습윤",1,IF(F42="양호",0,IF(F42="건조",0)))) -> 0 | L42: =IF(G42<10,0,IF(G42<30,1,IF(G42>=30,2))) -> 0 | M42: =IF(H42="-",0,1) -> 0 | N42: =SUM(I42:M42) -> 3 | O42: =IF(N42<6,"일반",IF(N42<9,"우선",IF(N42>=9,"긴급"))) -> 일반 | S42: 경기고속 삼거리 도로
...

Sheet V1
A2: ○ 2025년 등급별 손상구간 상세위치
A4: 손상구간번호(평가등급) | B4: 조사 위치도 | C4: 지번 주소 (도로명 주소)
A5: =RIGHT(RawData!$A$2,2)&"-"&RawData!$C$2&"-"&RawData!A6 -> 25-성남시-1 | C5: =IF(RawData!S6="","-",RawData!S6) -> 하나은행 앞 반대도로
A6: =RIGHT(RawData!$A$2,2)&"-"&RawData!$C$2&"-"&RawData!A7 -> 25-성남시-2 | C6: =IF(RawData!S7="","-",RawData!S7) -> 상록마을(임광/보성) 미켈란쉐르빌 앞 버스정류장
A7: =RIGHT(RawData!$A$2,2)&"-"&RawData!$C$2&"-"&RawData!A8 -> 25-성남시-3 | C7: =IF(RawData!S8="","-",RawData!S8) -> 미켈란쉐르빌 B동 앞 맞음편 보도
A8: =RIGHT(RawData!$A$2,2)&"-"&RawData!$C$2&"-"&RawData!A9 -> 25-성남시-4 | C8: =IF(RawData!S9="","-",RawData!S9) -> 야생화지하보도 양차선도로
A9: =RIGHT(RawData!$A$2,2)&"-"&RawData!$C$2&"-"&RawData!A10 -> 25-성남시-5 | C9: =IF(RawData!S10="","-",RawData!S10) -> 상록마을 버스정류장 앞 양차선도로
A10: =RIGHT(RawData!$A$2,2)&"-"&RawData!$C$2&"-"&RawData!A11 -> 25-성남시-6 | C10: =IF(RawData!S11="","-",RawData!S11) -> 금곡사거리 도로
A11: =RIGHT(RawData!$A$2,2)&"-"&RawData!$C$2&"-"&RawData!A12 -> 25-성남시-7 | C11: =IF(RawData!S12="","-",RawData!S12) -> 분당경영고등학교 앞 도로
A12: =RIGHT(RawData!$A$2,2)&"-"&RawData!$C$2&"-"&RawData!A13 -> 25-성남시-8 | C12: =IF(RawData!S13="","-",RawData!S13) -> #연결선 환기구 앞 도로
A13: =RIGHT(RawData!$A$2,2)&"-"&RawData!$C$2&"-"&RawData!A14 -> 25-성남시-9 | C13: =IF(RawData!S14="","-",RawData!S14) -> 청솔주공6단지 버스정류장 앞 도로
A14: =RIGHT(RawData!$A$2,2)&"-"&RawData!$C$2&"-"&RawData!A15 -> 25-성남시-10 | C14: =IF(RawData!S15="","-",RawData!S15) -> 청솔마을 사거리 앞 도로
A15: =RIGHT(RawData!$A$2,2)&"-"&RawData!$C$2&"-"&RawData!A16 -> 25-성남시-11 | C15: =IF(RawData!S16="","-",RawData!S16) -> 청솔마을성원7단지 아파트707동 도로
A16: =RIGHT(RawData!$A$2,2)&"-"&RawData!$C$2&"-"&RawData!A17 -> 25-성남시-12 | C16: =IF(RawData!S17="","-",RawData!S17) -> 청솔마을성원7단지 아파트706동 도로
... A42: =RIGHT(RawData!$A$2,2)&"-"&RawData!$C$2&"-"&RawData!A43 -> 25-성남시-38 | C42: =IF(RawData!S43="","-",RawData!S43) -> 강원철물건재 앞 도로

Sheet V2
A2: ○ 육안조사 결과표
A4: 광역시도명 | C4: 서군구명 | E4: 대상시설명 | G4: 조사기간 | J4: 시설물관리자 | M4: 조사자
A5: 경기도 | C5: 성남시 | E5: 신분당선 | G5: 2025-03-17~2025-05-31 | J5: 신분당선 | M5: 기술참여자 명단 참조
A7: 순번 | B7: 조사측선명 | C7: 손상구분번호 | D7: 조사결과 | I7: 평가항목별 점수 | N7: 평가점수 | O7: 평가등급 | P7: 조사자 의견
D8: 침하(mm) | E8: 균열 | F8: 습윤 | G8: 노후도(년) | H8: 지반침하 발생 등의 이력1) (1년 이내) | I8: 침하 | J8: 균열 | K8: 습윤 | L8: 노후도 | M8: 보수보강이력
A9: 1 | B9: =RawData!B6 -> 성남대로 | C9: =RIGHT(RawData!$A$2,2)&"-"&RawData!$C$2&"-"&RawData!A6 -> 25-성남시-1 | D9: =RawData!D6 -> 양호 | E9: =RawData!E6 -> 종균열 횡균열 | F9: =RawData!F6 -> 건조 | G9: =RawData!G6 -> 9.3 | H9: =RawData!H6 -> - | I9: =IF(D9="양호",0,IF(D9>=100,9,IF(D9>=50,3,IF(D9<50,0)))) -> 0 | J9: =IF(E9="거북등",3,IF(RIGHT(E9,2)="균열",1,IF(E9="-",0))) -> 1 | K9: =IF(F9="유출",9,IF(F9="습윤",1,IF(F9="양호",0,IF(F9="건조",0)))) -> 0 | L9: =IF(G9<10,0,IF(G9<30,1,IF(G9>=30,2))) -> 0 | M9: =IF(H9="-",0,1) -> 0 | N9: =SUM(I9:M9) -> 1 | O9: =IF(N9<6,"일반",IF(N9<9,"우선",IF(N9>=9,"긴급"))) -> 일반 | P9: =RawData!P6 -> 0
A10: 2 | B10: =RawData!B7 -> 성남대로 | C10: =RIGHT(RawData!$A$2,2)&"-"&RawData!$C$2&"-"&RawData!A7 -> 25-성남시-2 | D10: =RawData!D7 -> 양호 | E10: =RawData!E7 -> 횡균열 | F10: =RawData!F7 -> 건조 | G10: =RawData!G7 -> 9.3 | H10: =RawData!H7 -> - | I10: =IF(D10="양호",0,IF(D10>=100,9,IF(D10>=50,3,IF(D10<50,0)))) -> 0 | J10: =IF(E10="거북등",3,IF(RIGHT(E10,2)="균열",1,IF(E10="-",0))) -> 1 | K10: =IF(F10="유출",9,IF(F10="습윤",1,IF(F10="양호",0,IF(F10="건조",0)))) -> 0 | L10: =IF(G10<10,0,IF(G10<30,1,IF(G10>=30,2))) -> 0 | M10: =IF(H10="-",0,1) -> 0 | N10: =SUM(I10:M10) -> 1 | O10: =IF(N10<6,"일반",IF(N10<9,"우선",IF(N10>=9,"긴급"))) -> 일반 | P10: =RawData!P7 -> 0
A11: 3 | B11: =RawData!B8 -> 성남대로 | C11: =RIGHT(RawData!$A$2,2)&"-"&RawData!$C$2&"-"&RawData!A8 -> 25-성남시-3 | D11: =RawData!D8 -> 보통 | E11: =RawData!E8 -> - | F11: =RawData!F8 -> 건조 | G11: =RawData!G8 -> 9.3 | H11: =RawData!H8 -> - | I11: =IF(D11="양호",0,IF(D11>=100,9,IF(D11>=50,3,IF(D11<50,0)))) -> 9 | J11: =IF(E11="거북등",3,IF(RIGHT(E11,2)="균열",1,IF(E11="-",0))) -> 0 | K11: =IF(F11="유출",9,IF(F11="습윤",1,IF(F11="양호",0,IF(F11="건조",0)))) -> 0 | L11: =IF(G11<10,0,IF(G11<30,1,IF(G11>=30,2))) -> 0 | M11: =IF(H11="-",0,1) -> 0 | N11: =SUM(I11:M11) -> 9 | O11: =IF(N11<6,"일반",IF(N11<9,"우선",IF(N11>=9,"긴급"))) -> 긴급 | P11: =RawData!P8 -> 보도침하 8cm
A12: 4 | B12: =RawData!B9 -> 성남대로 | C12: =RIGHT(RawData!$A$2,2)&"-"&RawData!$C$2&"-"&RawData!A9 -> 25-성남시-4 | D12: =RawData!D9 -> 양호 | E12: =RawData!E9 -> 거북등 | F12: =RawData!F9 -> 건조 | G12: =RawData!G9 -> 9.3 | H12: =RawData!H9 -> - | I12: =IF(D12="양호",0,IF(D12>=100,9,IF(D12>=50,3,IF(D12<50,0)))) -> 0 | J12: =IF(E12="거북등",3,IF(RIGHT(E12,2)="균열",1,IF(E12="-",0))) -> 3 | K12: =IF(F12="유출",9,IF(F12="습윤",1,IF(F12="양호",0,IF(F12="건조",0)))) -> 0 | L12: =IF(G12<10,0,IF(G12<30,1,IF(G12>=30,2))) -> 0 | M12: =IF(H12="-",0,1) -> 0 | N12: =SUM(I12:M12) -> 3 | O12: =IF(N12<6,"일반",IF(N12<9,"우선",IF(N12>=9,"긴급"))) -> 일반 | P12: =RawData!P9 -> 0
A13: 5 | B13: =RawData!B10 -> 성남대로 | C13: =RIGHT(RawData!$A$2,2)&"-"&RawData!$C$2&"-"&RawData!A10 -> 25-성남시-5 | D13: =RawData!D10 -> 양호 | E13: =RawData!E10 -> 거북등 | F13: =RawData!F10 -> 건조 | G13: =RawData!G10 -> 9.3 | H13: =RawData!H10 -> - | I13: =IF(D13="양호",0,IF(D13>=100,9,IF(D13>=50,3,IF(D13<50,0)))) -> 0 | J13: =IF(E13="거북등",3,IF(RIGHT(E13,2)="균열",1,IF(E13="-",0))) -> 3 | K13: =IF(F13="유출",9,IF(F13="습윤",1,IF(F13="양호",0,IF(F13="건조",0)))) -> 0 | L13: =IF(G13<10,0,IF(G13<30,1,IF(G13>=30,2))) -> 0 | M13: =IF(H13="-",0,1) -> 0 | N13: =SUM(I13:M13) -> 3 | O13: =IF(N13<6,"일반",IF(N13<9,"우선",IF(N13>=9,"긴급"))) -> 일반 | P13: =RawData!P10 -> 0
A14: 6 | B14: =RawData!B11 -> 성남대로 | C14: =RIGHT(RawData!$A$2,2)&"-"&RawData!$C$2&"-"&RawData!A11 -> 25-성남시-6 | D14: =RawData!D11 -> 양호 | E14: =RawData!E11 -> 거북등 | F14: =RawData!F11 -> 건조 | G14: =RawData!G11 -> 9.3 | H14: =RawData!H11 -> - | I14: =IF(D14="양호",0,IF(D14>=100,9,IF(D14>=50,3,IF(D14<50,0)))) -> 0 | J14: =IF(E14="거북등",3,IF(RIGHT(E14,2)="균열",1,IF(E14="-",0))) -> 3 | K14: =IF(F14="유출",9,IF(F14="습윤",1,IF(F14="양호",0,IF(F14="건조",0)))) -> 0 | L14: =IF(G14<10,0,IF(G14<30,1,IF(G14>=30,2))) -> 0 | M14: =IF(H14="-",0,1) -> 0 | N14: =SUM(I14:M14) -> 3 | O14: =IF(N14<6,"일반",IF(N14<9,"우선",IF(N14>=9,"긴급"))) -> 일반 | P14: =RawData!P11 -> 0
A15: 7 | B15: =RawData!B12 -> 성남대로 | C15: =RIGHT(RawData!$A$2,2)&"-"&RawData!$C$2&"-"&RawData!A12 -> 25-성남시-7 | D15: =RawData!D12 -> 양호 | E15: =RawData!E12 -> 횡균열 | F15: =RawData!F12 -> 건조 | G15: =RawData!G12 -> 9.3 | H15: =RawData!H12 -> - | I15: =IF(D15="양호",0,IF(D15>=100,9,IF(D15>=50,3,IF(D15<50,0)))) -> 0 | J15: =IF(E15="거북등",3,IF(RIGHT(E15,2)="균열",1,IF(E15="-",0))) -> 1 | K15: =IF(F15="유출",9,IF(F15="습윤",1,IF(F15="양호",0,IF(F15="건조",0)))) -> 0 | L15: =IF(G15<10,0,IF(G15<30,1,IF(G15>=30,2))) -> 0 | M15: =IF(H15="-",0,1) -> 0 | N15: =SUM(I15:M15) -> 1 | O15: =IF(N15<6,"일반",IF(N15<9,"우선",IF(N15>=9,"긴급"))) -> 일반 | P15: =RawData!P12 -> 0
A16: 8 | B16: =RawData!B13 -> 성남대로 | C16: =RIGHT(RawData!$A$2,2)&"-"&RawData!$C$2&"-"&RawData!A13 -> 25-성남시-8 | D16: =RawData!D13 -> 양호 | E16: =RawData!E13 -> 거북등 | F16: =RawData!F13 -> 건조 | G16: =RawData!G13 -> 9.3 | H16: =RawData!H13 -> - | I16: =IF(D16="양호",0,IF(D16>=100,9,IF(D16>=50,3,IF(D16<50,0)))) -> 0 | J16: =IF(E16="거북등",3,IF(RIGHT(E16,2)="균열",1,IF(E16="-",0))) -> 3 | K16: =IF(F16="유출",9,IF(F16="습윤",1,IF(F16="양호",0,IF(F16="건조",0)))) -> 0 | L16: =IF(G16<10,0,IF(G16<30,1,IF(G16>=30,2))) -> 0 | M16: =IF(H16="-",0,1) -> 0 | N16: =SUM(I16:M16) -> 3 | O16: =IF(N16<6,"일반",IF(N16<9,"우선",IF(N16>=9,"긴급"))) -> 일반 | P16: =RawData!P13 -> 5cm미만 침하
A17: 9 | B17: =RawData!B14 -> 성남대로 | C17: =RIGHT(RawData!$A$2,2)&"-"&RawData!$C$2&"-"&RawData!A14 -> 25-성남시-9 | D17: =RawData!D14 -> 양호 | E17: =RawData!E14 -> 거북등 | F17: =RawData!F14 -> 건조 | G17: =RawData!G14 -> 9.3 | H17: =RawData!H14 -> - | I17: =IF(D17="양호",0,IF(D17>=100,9,IF(D17>=50,3,IF(D17<50,0)))) -> 0 | J17: =IF(E17="거북등",3,IF(RIGHT(E17,2)="균열",1,IF(E17="-",0))) -> 3 | K17: =IF(F17="유출",9,IF(F17="습윤",1,IF(F17="양호",0,IF(F17="건조",0)))) -> 0 | L17: =IF(G17<10,0,IF(G17<30,1,IF(G17>=30,2))) -> 0 | M17: =IF(H17="-",0,1) -> 0 | N17: =SUM(I17:M17) -> 3 | O17: =IF(N17<6,"일반",IF(N17<9,"우선",IF(N17>=9,"긴급"))) -> 일반 | P17: =RawData!P14 -> 0
A18: 10 | B18: =RawData!B15 -> 성남대로 | C18: =RIGHT(RawData!$A$2,2)&"-"&RawData!$C$2&"-"&RawData!A15 -> 25-성남시-10 | D18: =RawData!D15 -> 양호 | E18: =RawData!E15 -> 거북등 | F18: =RawData!F15 -> 건조 | G18: =RawData!G15 -> 9.3 | H18: =RawData!H15 -> - | I18: =IF(D18="양호",0,IF(D18>=100,9,IF(D18>=50,3,IF(D18<50,0)))) -> 0 | J18: =IF(E18="거북등",3,IF(RIGHT(E18,2)="균열",1,IF(E18="-",0))) -> 3 | K18: =IF(F18="유출",9,IF(F18="습윤",1,IF(F18="양호",0,IF(F18="건조",0)))) -> 0 | L18: =IF(G18<10,0,IF(G18<30,1,IF(G18>=30,2))) -> 0 | M18: =IF(H18="-",0,1) -> 0 | N18: =SUM(I18:M18) -> 3 | O18: =IF(N18<6,"일반",IF(N18<9,"우선",IF(N18>=9,"긴급"))) -> 일반 | P18: =RawData!P15 -> 0
A19: 11 | B19: =RawData!B16 -> 성남대로 | C19: =RIGHT(RawData!$A$2,2)&"-"&RawData!$C$2&"-"&RawData!A16 -> 25-성남시-11 | D19: =RawData!D16 -> 양호 | E19: =RawData!E16 -> 거북등 | F19: =RawData!F16 -> 건조 | G19: =RawData!G16 -> 9.3 | H19: =RawData!H16 -> - | I19: =IF(D19="양호",0,IF(D19>=100,9,IF(D19>=50,3,IF(D19<50,0)))) -> 0 | J19: =IF(E19="거북등",3,IF(RIGHT(E19,2)="균열",1,IF(E19="-",0))) -> 3 | K19: =IF(F19="유출",9,IF(F19="습윤",1,IF(F19="양호",0,IF(F19="건조",0)))) -> 0 | L19: =IF(G19<10,0,IF(G19<30,1,IF(G19>=30,2))) -> 0 | M19: =IF(H19="-",0,1) -> 0 | N19: =SUM(I19:M19) -> 3 | O19: =IF(N19<6,"일반",IF(N19<9,"우선",IF(N19>=9,"긴급"))) -> 일반 | P19: =RawData!P16 -> 0
A20: 12 | B20: =RawData!B17 -> 성남대로 | C20: =RIGHT(RawData!$A$2,2)&"-"&RawData!$C$2&"-"&RawData!A17 -> 25-성남시-12 | D20: =RawData!D17 -> 양호 | E20: =RawData!E17 -> 횡균열 | F20: =RawData!F17 -> 건조 | G20: =RawData!G17 -> 9.3 | H20: =RawData!H17 -> - | I20: =IF(D20="양호",0,IF(D20>=100,9,IF(D20>=50,3,IF(D20<50,0)))) -> 0 | J20: =IF(E20="거북등",3,IF(RIGHT(E20,2)="균열",1,IF(E20="-",0))) -> 1 | K20: =IF(F20="유출",9,IF(F20="습윤",1,IF(F20="양호",0,IF(F20="건조",0)))) -> 0 | L20: =IF(G20<10,0,IF(G20<30,1,IF(G20>=30,2))) -> 0 | M20: =IF(H20="-",0,1) -> 0 | N20: =SUM(I20:M20) -> 1 | O20: =IF(N20<6,"일반",IF(N20<9,"우선",IF(N20>=9,"긴급"))) -> 일반 | P20: =RawData!P17 -> 0
... A50: 42 | B50: =RawData!B47 -> 0 | C50: =RIGHT(RawData!$A$2,2)&"-"&RawData!$C$2&"-"&RawData!A47 -> 25-성남시- | D50: =RawData!D47 -> 0 | E50: =RawData!E47 -> 0 | F50: =RawData!F47 -> 0 | G50: =RawData!G47 -> 0 | H50: =RawData!H47 -> 0 | I50: =IF(D50="양호",0,IF(D50>=100,9,IF(D50>=50,3,IF(D50<50,0)))) -> 0 | J50: =IF(E50="거북등",3,IF(RIGHT(E50,2)="균열",1,IF(E50="-",0))) -> FALSE | K50: =IF(F50="유출",9,IF(F50="습윤",1,IF(F50="양호",0,IF(F50="건조",0)))) -> FALSE | L50: =IF(G50<10,0,IF(G50<30,1,IF(G50>=30,2))) -> 0 | M50: =IF(H50="-",0,1) -> 1 | N50: =SUM(I50:M50) -> 1 | O50: =IF(N50<6,"일반",IF(N50<9,"우선",IF(N50>=9,"긴급"))) -> 일반 | P50: =RawData!P47 -> 0

Sheet 범례
A1: 시행년도 | B1: 시행사 구분 | C1: 권역구 구분 | F1: 양호 | G1: 보통 | H1: 불량 | J1: 총 점수 | K1: 평가등급 | L1: 비고
A2: 2018 | B2: 신분당 | C2: 강남구 | E2: 침하 | F2: 0 | G2: 3 | H2: 9 | J2: 3~5 | K2: 일반 | L2: -
A3: 2019 | B3: 경기철도 | C3: 서초구 | E3: 균열 | F3: 0 | G3: 1 | H3: 3 | J3: 6~8 | K3: 우선 | L3: 육안조사서 작성
A4: 2020 | B4: 새서울철도 | C4: 성남시 | E4: 습윤 | F4: 0 | G4: 1~3 | H4: 9 | J4: 9 이상 | K4: 긴급 | L4: 육안조사서 작성
A5: 2021 | C5: 용인시 | E5: 노후도 | F5: 0 | G5: 1 | H5: 2
A6: 2022 | C6: 수원시 | E6: 지반침하 등의 발생이력 | F6: 0 | G6: 1 | H6: 1
A7: 2023
A8: 2024
A9: 2025
