Workbook

Sheet RawData
B1: 시행사 구분 | C1: 권역구 구분
B2: 경기철도㈜ | C2: 용인시
A4: 시행년도 | B4: 순번 | C4: 조사측선명 | D4: 손상구분번호 | E4: 침하(mm) | F4: 균열 | G4: 습윤 | H4: 노후도(년) | I4: 지반침하발생이력 | J4: 침하점수 | K4: 균열점수 | L4: 습윤점수 | M4: 노후도점수 | N4: 보수보강이력 | O4: 평가점수 | P4: 평가등급 | Q4: 조사자의견 | R4: 인접지번주소 | S4: 조사위치도 | T4: 부가정보1 | U4: 부가정보2
A5: 2026 | B5: 1 | C5: 신수로 | D5: 26-용인시-01 | E5: 양호 | F5: 종횡균열 | G5: 양호 | H5: 10.3 | I5: - | J5: 0 | K5: 1 | L5: 0 | M5: 1 | N5: 0 | O5: 2 | P5: 일반 | Q5: - | R5: 동천동186-12 | T5: 바다생협대광어_용인본점(신수로783)
A6: 2026 | B6: 2 | C6: 신수로 | D6: 26-용인시-02 | E6: 양호 | F6: 거북등 | G6: 양호 | H6: 10.3 | I6: - | J6: 0 | K6: 3 | L6: 0 | M6: 1 | N6: 0 | O6: 4 | P6: 일반 | Q6: - | R6: 만당주유소 앞 삼거리 | T6: 만당주유소 앞 삼거리(신수로781)
A7: 2026 | B7: 3 | C7: 신수로 | D7: 26-용인시-03 | E7: 보통 | F7: 종횡균열 | G7: 양호 | H7: 10.3 | I7: - | J7: 3 | K7: 1 | L7: 0 | M7: 1 | N7: 0 | O7: 5 | P7: 일반 | Q7: 7cm 침하 | R7: 동천동899 | T7: 동천역 #3번출구 신호등 앞 도로(신수로767) | U7: 현장확인필요
A8: 2026 | B8: 4 | C8: 신수로 | D8: 26-용인시-04 | E8: 양호 | F8: 거북등 | G8: 양호 | H8: 10.3 | I8: - | J8: 0 | K8: 3 | L8: 0 | M8: 1 | N8: 0 | O8: 4 | P8: 일반 | Q8: - | R8: 동천동899 | T8: 동천역 #3번출구 앞 도로(신수로767)
A9: 2026 | B9: 5 | C9: 신수로 | D9: 26-용인시-05 | E9: 양호 | F9: - | G9: 양호 | H9: 10.3 | I9: - | J9: 0 | K9: 0 | L9: 0 | M9: 1 | N9: 0 | O9: 1 | P9: 일반 | Q9: 5cm 보도침하 | R9: 동천동899 | T9: 동천역 E/V_#2호기 앞 보도(신수로767) | U9: 현장확인필요
A10: 2026 | B10: 6 | C10: 신수로 | D10: 26-용인시-06 | E10: 양호 | F10: 종균열 | G10: 양호 | H10: 10.3 | I10: - | J10: 0 | K10: 1 | L10: 0 | M10: 1 | N10: 0 | O10: 2 | P10: 일반 | Q10: - | R10: 동천동899 | T10: 동천역 E/V_#2호기 앞 도로(신수로767)
A11: 2026 | B11: 7 | C11: 신수로 | D11: 26-용인시-07 | E11: 양호 | F11: 거북등 | G11: 양호 | H11: 10.3 | I11: - | J11: 0 | K11: 3 | L11: 0 | M11: 1 | N11: 0 | O11: 4 | P11: 일반 | Q11: - | R11: 동천동900 | T11: 상선종점 피난계단 앞 도로
A12: 2026 | B12: 8 | C12: 신수로 | D12: 26-용인시-08 | E12: 보통 | F12: - | G12: 양호 | H12: 10.3 | I12: - | J12: 3 | K12: 0 | L12: 0 | M12: 1 | N12: 0 | O12: 4 | P12: 일반 | Q12: 7~9cm 보도침하 | R12: 동천동900 | T12: 상선종점 피난계단 뒤 보도 | U12: 현장확인필요
A13: 2026 | B13: 9 | C13: 신수로 | D13: 26-용인시-09 | E13: 양호 | F13: 종횡균열 | G13: 양호 | H13: 10.3 | I13: - | J13: 0 | K13: 1 | L13: 0 | M13: 1 | N13: 0 | O13: 2 | P13: 일반 | Q13: - | R13: 동천동901 | T13: 용인푸르지오 모델하우스 앞 도로(손곡로10)
A14: 2026 | B14: 10 | C14: 신수로 | D14: 26-용인시-10 | E14: 양호 | F14: 거북등 | G14: 양호 | H14: 10.3 | I14: - | J14: 0 | K14: 3 | L14: 0 | M14: 1 | N14: 0 | O14: 4 | P14: 일반 | Q14: - | R14: 동천동901 | T14: 현대건설 힐스테이트 모델하우스 앞 양차선(손곡로10)
A15: 2026 | B15: 11 | C15: 신수로 | D15: 26-용인시-11 | E15: 양호 | F15: 거북등 | G15: 양호 | H15: 10.3 | I15: - | J15: 0 | K15: 3 | L15: 0 | M15: 1 | N15: 0 | O15: 4 | P15: 일반 | Q15: - | R15: 풍덕천동860-6 | T15: 제네시스_수지 앞 도로(풍덕천로197번길11-2)
A16: 2026 | B16: 12 | C16: 풍덕천로 | D16: 26-용인시-12 | E16: 양호 | F16: - | G16: 양호 | H16: 10.3 | I16: - | J16: 0 | K16: 0 | L16: 0 | M16: 1 | N16: 0 | O16: 1 | P16: 일반 | Q16: 5cm이하 침하 | R16: 풍덕천동740-9 | T16: 돌담집 앞 도로(풍덕천로197번길3-2)
A17: 2026 | B17: 13 | C17: 풍덕천로 | D17: 26-용인시-13 | E17: 양호 | F17: 거북등 | G17: 양호 | H17: 10.3 | I17: - | J17: 0 | K17: 3 | L17: 0 | M17: 1 | N17: 0 | O17: 4 | P17: 일반 | Q17: - | R17: 풍덕천동740-9 | T17: 돌담집 앞 삼거리(풍덕천로197번길3-2)
A18: 2026 | B18: 14 | C18: 풍덕천로 | D18: 26-용인시-14 | E18: 양호 | F18: - | G18: 양호 | H18: 10.3 | I18: - | J18: 0 | K18: 0 | L18: 0 | M18: 1 | N18: 0 | O18: 1 | P18: 일반 | Q18: 5cm이하 침하 | R18: 풍덕천동742-8 | T18: 샤인노래방 앞 도로(풍덕천로197번길1)
A19: 2026 | B19: 15 | C19: 풍덕천로 | D19: 26-용인시-15 | E19: 양호 | F19: 거북등 | G19: 양호 | H19: 10.3 | I19: - | J19: 0 | K19: 3 | L19: 0 | M19: 1 | N19: 0 | O19: 4 | P19: 일반 | Q19: - | R19: 풍덕천동742 | T19: 덕윤프라자 앞 도로(풍덕천로191)
A20: 2026 | B20: 16 | C20: 풍덕천로 | D20: 26-용인시-16 | E20: 양호 | F20: 거북등 | G20: 양호 | H20: 10.3 | I20: - | J20: 0 | K20: 3 | L20: 0 | M20: 1 | N20: 0 | O20: 4 | P20: 일반 | Q20: - | R20: 풍덕천동735-7 | T20: 삼정빌딩 앞 도로(풍덕천로187-1)
A21: 2026 | B21: 17 | C21: 풍덕천로 | D21: 26-용인시-17 | E21: 양호 | F21: 거북등 | G21: 양호 | H21: 10.3 | I21: - | J21: 0 | K21: 3 | L21: 0 | M21: 1 | N21: 0 | O21: 4 | P21: 일반 | Q21: - | R21: 풍덕천동732-6 | T21: 용인서부소방서수지119안전센터 앞 도로(풍덕천로177)
A22: 2026 | B22: 18 | C22: 풍덕천로 | D22: 26-용인시-18 | E22: 양호 | F22: 거북등 | G22: 양호 | H22: 10.3 | I22: - | J22: 0 | K22: 3 | L22: 0 | M22: 1 | N22: 0 | O22: 4 | P22: 일반 | Q22: - | R22: 풍덕천동703-4 | T22: 수지분당 공인중개사사무소 앞 도로(풍덕천로169)
A23: 2026 | B23: 19 | C23: 풍덕천로 | D23: 26-용인시-19 | E23: 양호 | F23: 거북등 | G23: 양호 | H23: 10.3 | I23: - | J23: 0 | K23: 3 | L23: 0 | M23: 1 | N23: 0 | O23: 4 | P23: 일반 | Q23: - | R23: 풍덕천동703 | T23: 동보아파트 놀이터 앞 도로(풍덕천로155)
A24: 2026 | B24: 20 | C24: 풍덕천로 | D24: 26-용인시-20 | E24: 양호 | F24: 거북등 | G24: 양호 | H24: 10.3 | I24: - | J24: 0 | K24: 3 | L24: 0 | M24: 1 | N24: 0 | O24: 4 | P24: 일반 | Q24: - | R24: 풍덕천동703 | T24: 동보아파트 서울치과의원 앞 양차선(풍덕천로161)
... A76: 2026 | B76: 72 | C76: 광교중앙로 | D76: 26-용인시-72 | E76: 양호 | F76: 종균열 | G76: 양호 | H76: 10.3 | I76: - | J76: 0 | K76: 1 | L76: 0 | M76: 1 | N76: 0 | O76: 2 | P76: 일반 | Q76: - | R76: 상현동1066 | T76: 진고개통로
A77: 2025 | B77: 1 | C77: 신수로 | D77: 25-용인시-1 | E77: 양호 | F77: 거북등 | G77: 건조 | H77: 9.3 | I77: - | J77: 0 | K77: 3 | L77: 0 | M77: 0 | N77: 0 | O77: 3 | P77: 일반 | R77: 동천동 186-12 | T77: 임창정 세겹살 앞 도로 (신수로)
A78: 2025 | B78: 2 | C78: 동천로 | D78: 25-용인시-2 | E78: 양호 | F78: 거북등 | G78: 건조 | H78: 9.3 | I78: - | J78: 0 | K78: 3 | L78: 0 | M78: 0 | N78: 0 | O78: 3 | P78: 일반 | R78: 동천동 325-728 | T78: 고가 앞 도로 (신수로)
A79: 2025 | B79: 3 | C79: 신수로 | D79: 25-용인시-3 | E79: 양호 | F79: 거북등 | G79: 건조 | H79: 9.3 | I79: - | J79: 0 | K79: 3 | L79: 0 | M79: 0 | N79: 0 | O79: 3 | P79: 일반 | R79: 만당주유소앞삼거리 | T79: 만당주유소 앞 삼거리 도로 (신수로)
A80: 2025 | B80: 4 | C80: 신수로 | D80: 25-용인시-4 | E80: 보통 | F80: - | G80: 건조 | H80: 9.3 | I80: - | J80: 3 | K80: 0 | L80: 0 | M80: 0 | N80: 0 | O80: 3 | P80: 일반 | Q80: 침하 9cm | R80: 동천동 207 | T80: 동천역 하선피난계단 앞 도로 (신수로)
A81: 2025 | B81: 5 | C81: 신수로 | D81: 25-용인시-5 | E81: 양호 | F81: 거북등 | G81: 건조 | H81: 9.3 | I81: - | J81: 0 | K81: 3 | L81: 0 | M81: 0 | N81: 0 | O81: 3 | P81: 일반 | Q81: 침하 5cm미만 | R81: 동천동 207-3 | T81: 자전거 거치대 앞 도로 (신수로)
A82: 2025 | B82: 6 | C82: 신수로 | D82: 25-용인시-6 | E82: 양호 | F82: 거북등 | G82: 건조 | H82: 9.3 | I82: - | J82: 0 | K82: 3 | L82: 0 | M82: 0 | N82: 0 | O82: 3 | P82: 일반 | R82: 동천동 899 | T82: 동천역 #2출구 앞 도로 (신수로)
A83: 2025 | B83: 7 | C83: 신수로 | D83: 25-용인시-7 | E83: 양호 | F83: - | G83: 건조 | H83: 9.3 | I83: - | J83: 0 | K83: 0 | L83: 0 | M83: 0 | N83: 0 | O83: 0 | P83: 일반 | Q83: 보도침하 5cm미만 | R83: 동천동 325-21 | T83: 동천역 #1출구 앞 보도 (신수로)
A84: 2025 | B84: 8 | C84: 신수로 | D84: 25-용인시-8 | E84: 양호 | F84: 횡균열 | G84: 건조 | H84: 9.3 | I84: - | J84: 0 | K84: 1 | L84: 0 | M84: 0 | N84: 0 | O84: 1 | P84: 일반 | R84: 동천동 325-710 | T84: 동천역 상선 피난계단 맞음편 도로 (신수로)
A85: 2025 | B85: 9 | C85: 신수로 | D85: 25-용인시-9 | E85: 양호 | F85: 종균열 | G85: 건조 | H85: 9.3 | I85: - | J85: 0 | K85: 1 | L85: 0 | M85: 0 | N85: 0 | O85: 1 | P85: 일반 | Q85: 침하3cm | R85: 동천동 901 | T85: 푸르지오 건물 앞 도로 (신수로)
A86: 2025 | B86: 10 | C86: 신수로 | D86: 25-용인시-10 | E86: 양호 | F86: 거북등 | G86: 건조 | H86: 9.3 | I86: - | J86: 0 | K86: 3 | L86: 0 | M86: 0 | N86: 0 | O86: 3 | P86: 일반 | R86: 동천동 325-731 | T86: 푸르지오 맞음편 도로 (신수로)
A87: 2025 | B87: 11 | C87: 신수로 | D87: 25-용인시-11 | E87: 양호 | F87: 거북등 | G87: 건조 | H87: 9.3 | I87: - | J87: 0 | K87: 3 | L87: 0 | M87: 0 | N87: 0 | O87: 3 | P87: 일반 | R87: 동천동 901 | T87: 힐스테이트 앞 도로 (신수로)
A88: 2025 | B88: 12 | C88: 신수로 | D88: 25-용인시-12 | E88: 양호 | F88: 거북등 | G88: 건조 | H88: 9.3 | I88: - | J88: 0 | K88: 3 | L88: 0 | M88: 0 | N88: 0 | O88: 3 | P88: 일반 | R88: 조달청품질관리단앞삼거리 | T88: 조달청 품질관리단 앞 삼거리 도로 (풍덕천로)
A89: 2025 | B89: 13 | C89: 신수로 | D89: 25-용인시-13 | E89: 양호 | F89: 종균열 | G89: 건조 | H89: 9.3 | I89: - | J89: 0 | K89: 1 | L89: 0 | M89: 0 | N89: 0 | O89: 1 | P89: 일반 | R89: 풍덕천동 853-1 | T89: 레스피아 통로 앞 도로 (풍덕천로)
A90: 2025 | B90: 14 | C90: 신수로 | D90: 25-용인시-14 | E90: 양호 | F90: 거북등 | G90: 건조 | H90: 9.3 | I90: - | J90: 0 | K90: 3 | L90: 0 | M90: 0 | N90: 0 | O90: 3 | P90: 일반 | R90: 풍덕천동 860 | T90: 제네시스 수지 앞 도로 (풍덕천로)
A91: 2025 | B91: 15 | C91: 풍덕천로 | D91: 25-용인시-15 | E91: 양호 | F91: 종균열 | G91: 건조 | H91: 9.3 | I91: - | J91: 0 | K91: 1 | L91: 0 | M91: 0 | N91: 0 | O91: 1 | P91: 일반 | Q91: 침하4cm | R91: 풍덕천동 740-9 | T91: 다복 앞 도로 (풍덕천로)
A92: 2025 | B92: 16 | C92: 풍덕천로 | D92: 25-용인시-16 | E92: 보통 | F92: - | G92: 건조 | H92: 9.3 | I92: - | J92: 3 | K92: 0 | L92: 0 | M92: 0 | N92: 0 | O92: 3 | P92: 일반 | Q92: 침하8cm | R92: 풍덕천동 742-8 | T92: 샤인노래방 앞 도로 (풍덕천로)
...

Sheet V2
A2: ○ 육안조사 결과표
A4: 광역시도명 | C4: 서군구명 | E4: 대상시설명 | G4: 조사기간 | J4: 시설물관리자 | M4: 조사자
A5: 경기도 | C5: =RawData!C2 -> 용인시 | E5: 신분당선 | G5: 2026-03-17~2026-05-27 | J5: =[1]RawData!B2 -> 2026 | M5: 기술참여자 명단 참조
A7: 순번 | B7: 조사측선명 | C7: 손상구분번호 | D7: 조사결과 | I7: 평가항목별 점수 | N7: 평가점수 | O7: 평가등급 | P7: 조사자 의견
D8: 침하(mm) | E8: 균열 | F8: 습윤 | G8: 노후도(년) | H8: 지반침하 발생 등의 이력1) (1년 이내) | I8: 침하 | J8: 균열 | K8: 습윤 | L8: 노후도 | M8: 보수보강이력
A9: =RIGHT(RawData!B5,2) -> 1 | B9: =RawData!C5 -> 신수로 | C9: =RawData!D5 -> 26-용인시-01 | D9: =RawData!E5 -> 양호 | E9: =RawData!F5 -> 종횡균열 | F9: =RawData!G5 -> 양호 | G9: =RawData!H5 -> 10.3 | H9: =RawData!I5 -> - | I9: =IF(D9="양호",0,IF(D9="보통",3,IF(D9="불량",9))) -> 0 | J9: =IF(E9="거북등",3,IF(RIGHT(E9,2)="균열",1,IF(E9="-",0))) -> 1 | K9: =IF(F9="유출",9,IF(F9="습윤",1,IF(F9="양호",0,IF(F9="건조",0)))) -> 0 | L9: =IF(G9>=30,2,IF(G9>=10,1,0)) -> 1 | M9: =IF(H9="-",0,1) -> 0 | N9: =SUM(I9:M9) -> 2 | O9: =IF(N9<6,"일반",IF(N9<9,"우선",IF(N9>=9,"긴급"))) -> 일반 | P9: =RawData!Q5 -> -
A10: =RIGHT(RawData!B6,2) -> 2 | B10: =RawData!C6 -> 신수로 | C10: =RawData!D6 -> 26-용인시-02 | D10: =RawData!E6 -> 양호 | E10: =RawData!F6 -> 거북등 | F10: =RawData!G6 -> 양호 | G10: =RawData!H6 -> 10.3 | H10: =RawData!I6 -> - | I10: =IF(D10="양호",0,IF(D10="보통",3,IF(D10="불량",9))) -> 0 | J10: =IF(E10="거북등",3,IF(RIGHT(E10,2)="균열",1,IF(E10="-",0))) -> 3 | K10: =IF(F10="유출",9,IF(F10="습윤",1,IF(F10="양호",0,IF(F10="건조",0)))) -> 0 | L10: =IF(G10>=30,2,IF(G10>=10,1,0)) -> 1 | M10: =IF(H10="-",0,1) -> 0 | N10: =SUM(I10:M10) -> 4 | O10: =IF(N10<6,"일반",IF(N10<9,"우선",IF(N10>=9,"긴급"))) -> 일반 | P10: =RawData!Q6 -> -
A11: =RIGHT(RawData!B7,2) -> 3 | B11: =RawData!C7 -> 신수로 | C11: =RawData!D7 -> 26-용인시-03 | D11: =RawData!E7 -> 보통 | E11: =RawData!F7 -> 종횡균열 | F11: =RawData!G7 -> 양호 | G11: =RawData!H7 -> 10.3 | H11: =RawData!I7 -> - | I11: =IF(D11="양호",0,IF(D11="보통",3,IF(D11="불량",9))) -> 3 | J11: =IF(E11="거북등",3,IF(RIGHT(E11,2)="균열",1,IF(E11="-",0))) -> 1 | K11: =IF(F11="유출",9,IF(F11="습윤",1,IF(F11="양호",0,IF(F11="건조",0)))) -> 0 | L11: =IF(G11>=30,2,IF(G11>=10,1,0)) -> 1 | M11: =IF(H11="-",0,1) -> 0 | N11: =SUM(I11:M11) -> 5 | O11: =IF(N11<6,"일반",IF(N11<9,"우선",IF(N11>=9,"긴급"))) -> 일반 | P11: =RawData!Q7 -> 7cm 침하
A12: =RIGHT(RawData!B8,2) -> 4 | B12: =RawData!C8 -> 신수로 | C12: =RawData!D8 -> 26-용인시-04 | D12: =RawData!E8 -> 양호 | E12: =RawData!F8 -> 거북등 | F12: =RawData!G8 -> 양호 | G12: =RawData!H8 -> 10.3 | H12: =RawData!I8 -> - | I12: =IF(D12="양호",0,IF(D12="보통",3,IF(D12="불량",9))) -> 0 | J12: =IF(E12="거북등",3,IF(RIGHT(E12,2)="균열",1,IF(E12="-",0))) -> 3 | K12: =IF(F12="유출",9,IF(F12="습윤",1,IF(F12="양호",0,IF(F12="건조",0)))) -> 0 | L12: =IF(G12>=30,2,IF(G12>=10,1,0)) -> 1 | M12: =IF(H12="-",0,1) -> 0 | N12: =SUM(I12:M12) -> 4 | O12: =IF(N12<6,"일반",IF(N12<9,"우선",IF(N12>=9,"긴급"))) -> 일반 | P12: =RawData!Q8 -> -
A13: =RIGHT(RawData!B9,2) -> 5 | B13: =RawData!C9 -> 신수로 | C13: =RawData!D9 -> 26-용인시-05 | D13: =RawData!E9 -> 양호 | E13: =RawData!F9 -> - | F13: =RawData!G9 -> 양호 | G13: =RawData!H9 -> 10.3 | H13: =RawData!I9 -> - | I13: =IF(D13="양호",0,IF(D13="보통",3,IF(D13="불량",9))) -> 0 | J13: =IF(E13="거북등",3,IF(RIGHT(E13,2)="균열",1,IF(E13="-",0))) -> 0 | K13: =IF(F13="유출",9,IF(F13="습윤",1,IF(F13="양호",0,IF(F13="건조",0)))) -> 0 | L13: =IF(G13>=30,2,IF(G13>=10,1,0)) -> 1 | M13: =IF(H13="-",0,1) -> 0 | N13: =SUM(I13:M13) -> 1 | O13: =IF(N13<6,"일반",IF(N13<9,"우선",IF(N13>=9,"긴급"))) -> 일반 | P13: =RawData!Q9 -> 5cm 보도침하
A14: =RIGHT(RawData!B10,2) -> 6 | B14: =RawData!C10 -> 신수로 | C14: =RawData!D10 -> 26-용인시-06 | D14: =RawData!E10 -> 양호 | E14: =RawData!F10 -> 종균열 | F14: =RawData!G10 -> 양호 | G14: =RawData!H10 -> 10.3 | H14: =RawData!I10 -> - | I14: =IF(D14="양호",0,IF(D14="보통",3,IF(D14="불량",9))) -> 0 | J14: =IF(E14="거북등",3,IF(RIGHT(E14,2)="균열",1,IF(E14="-",0))) -> 1 | K14: =IF(F14="유출",9,IF(F14="습윤",1,IF(F14="양호",0,IF(F14="건조",0)))) -> 0 | L14: =IF(G14>=30,2,IF(G14>=10,1,0)) -> 1 | M14: =IF(H14="-",0,1) -> 0 | N14: =SUM(I14:M14) -> 2 | O14: =IF(N14<6,"일반",IF(N14<9,"우선",IF(N14>=9,"긴급"))) -> 일반 | P14: =RawData!Q10 -> -
A15: =RIGHT(RawData!B11,2) -> 7 | B15: =RawData!C11 -> 신수로 | C15: =RawData!D11 -> 26-용인시-07 | D15: =RawData!E11 -> 양호 | E15: =RawData!F11 -> 거북등 | F15: =RawData!G11 -> 양호 | G15: =RawData!H11 -> 10.3 | H15: =RawData!I11 -> - | I15: =IF(D15="양호",0,IF(D15="보통",3,IF(D15="불량",9))) -> 0 | J15: =IF(E15="거북등",3,IF(RIGHT(E15,2)="균열",1,IF(E15="-",0))) -> 3 | K15: =IF(F15="유출",9,IF(F15="습윤",1,IF(F15="양호",0,IF(F15="건조",0)))) -> 0 | L15: =IF(G15>=30,2,IF(G15>=10,1,0)) -> 1 | M15: =IF(H15="-",0,1) -> 0 | N15: =SUM(I15:M15) -> 4 | O15: =IF(N15<6,"일반",IF(N15<9,"우선",IF(N15>=9,"긴급"))) -> 일반 | P15: =RawData!Q11 -> -
A16: =RIGHT(RawData!B12,2) -> 8 | B16: =RawData!C12 -> 신수로 | C16: =RawData!D12 -> 26-용인시-08 | D16: =RawData!E12 -> 보통 | E16: =RawData!F12 -> - | F16: =RawData!G12 -> 양호 | G16: =RawData!H12 -> 10.3 | H16: =RawData!I12 -> - | I16: =IF(D16="양호",0,IF(D16="보통",3,IF(D16="불량",9))) -> 3 | J16: =IF(E16="거북등",3,IF(RIGHT(E16,2)="균열",1,IF(E16="-",0))) -> 0 | K16: =IF(F16="유출",9,IF(F16="습윤",1,IF(F16="양호",0,IF(F16="건조",0)))) -> 0 | L16: =IF(G16>=30,2,IF(G16>=10,1,0)) -> 1 | M16: =IF(H16="-",0,1) -> 0 | N16: =SUM(I16:M16) -> 4 | O16: =IF(N16<6,"일반",IF(N16<9,"우선",IF(N16>=9,"긴급"))) -> 일반 | P16: =RawData!Q12 -> 7~9cm 보도침하
A17: =RIGHT(RawData!B13,2) -> 9 | B17: =RawData!C13 -> 신수로 | C17: =RawData!D13 -> 26-용인시-09 | D17: =RawData!E13 -> 양호 | E17: =RawData!F13 -> 종횡균열 | F17: =RawData!G13 -> 양호 | G17: =RawData!H13 -> 10.3 | H17: =RawData!I13 -> - | I17: =IF(D17="양호",0,IF(D17="보통",3,IF(D17="불량",9))) -> 0 | J17: =IF(E17="거북등",3,IF(RIGHT(E17,2)="균열",1,IF(E17="-",0))) -> 1 | K17: =IF(F17="유출",9,IF(F17="습윤",1,IF(F17="양호",0,IF(F17="건조",0)))) -> 0 | L17: =IF(G17>=30,2,IF(G17>=10,1,0)) -> 1 | M17: =IF(H17="-",0,1) -> 0 | N17: =SUM(I17:M17) -> 2 | O17: =IF(N17<6,"일반",IF(N17<9,"우선",IF(N17>=9,"긴급"))) -> 일반 | P17: =RawData!Q13 -> -
A18: =RIGHT(RawData!B14,2) -> 10 | B18: =RawData!C14 -> 신수로 | C18: =RawData!D14 -> 26-용인시-10 | D18: =RawData!E14 -> 양호 | E18: =RawData!F14 -> 거북등 | F18: =RawData!G14 -> 양호 | G18: =RawData!H14 -> 10.3 | H18: =RawData!I14 -> - | I18: =IF(D18="양호",0,IF(D18="보통",3,IF(D18="불량",9))) -> 0 | J18: =IF(E18="거북등",3,IF(RIGHT(E18,2)="균열",1,IF(E18="-",0))) -> 3 | K18: =IF(F18="유출",9,IF(F18="습윤",1,IF(F18="양호",0,IF(F18="건조",0)))) -> 0 | L18: =IF(G18>=30,2,IF(G18>=10,1,0)) -> 1 | M18: =IF(H18="-",0,1) -> 0 | N18: =SUM(I18:M18) -> 4 | O18: =IF(N18<6,"일반",IF(N18<9,"우선",IF(N18>=9,"긴급"))) -> 일반 | P18: =RawData!Q14 -> -
A19: =RIGHT(RawData!B15,2) -> 11 | B19: =RawData!C15 -> 신수로 | C19: =RawData!D15 -> 26-용인시-11 | D19: =RawData!E15 -> 양호 | E19: =RawData!F15 -> 거북등 | F19: =RawData!G15 -> 양호 | G19: =RawData!H15 -> 10.3 | H19: =RawData!I15 -> - | I19: =IF(D19="양호",0,IF(D19="보통",3,IF(D19="불량",9))) -> 0 | J19: =IF(E19="거북등",3,IF(RIGHT(E19,2)="균열",1,IF(E19="-",0))) -> 3 | K19: =IF(F19="유출",9,IF(F19="습윤",1,IF(F19="양호",0,IF(F19="건조",0)))) -> 0 | L19: =IF(G19>=30,2,IF(G19>=10,1,0)) -> 1 | M19: =IF(H19="-",0,1) -> 0 | N19: =SUM(I19:M19) -> 4 | O19: =IF(N19<6,"일반",IF(N19<9,"우선",IF(N19>=9,"긴급"))) -> 일반 | P19: =RawData!Q15 -> -
A20: =RIGHT(RawData!B16,2) -> 12 | B20: =RawData!C16 -> 풍덕천로 | C20: =RawData!D16 -> 26-용인시-12 | D20: =RawData!E16 -> 양호 | E20: =RawData!F16 -> - | F20: =RawData!G16 -> 양호 | G20: =RawData!H16 -> 10.3 | H20: =RawData!I16 -> - | I20: =IF(D20="양호",0,IF(D20="보통",3,IF(D20="불량",9))) -> 0 | J20: =IF(E20="거북등",3,IF(RIGHT(E20,2)="균열",1,IF(E20="-",0))) -> 0 | K20: =IF(F20="유출",9,IF(F20="습윤",1,IF(F20="양호",0,IF(F20="건조",0)))) -> 0 | L20: =IF(G20>=30,2,IF(G20>=10,1,0)) -> 1 | M20: =IF(H20="-",0,1) -> 0 | N20: =SUM(I20:M20) -> 1 | O20: =IF(N20<6,"일반",IF(N20<9,"우선",IF(N20>=9,"긴급"))) -> 일반 | P20: =RawData!Q16 -> 5cm이하 침하
... A80: =RIGHT(RawData!B76,2) -> 72 | B80: =RawData!C76 -> 광교중앙로 | C80: =RawData!D76 -> 26-용인시-72 | D80: =RawData!E76 -> 양호 | E80: =RawData!F76 -> 종균열 | F80: =RawData!G76 -> 양호 | G80: =RawData!H76 -> 10.3 | H80: =RawData!I76 -> - | I80: =IF(D80="양호",0,IF(D80="보통",3,IF(D80="불량",9))) -> 0 | J80: =IF(E80="거북등",3,IF(RIGHT(E80,2)="균열",1,IF(E80="-",0))) -> 1 | K80: =IF(F80="유출",9,IF(F80="습윤",1,IF(F80="양호",0,IF(F80="건조",0)))) -> 0 | L80: =IF(G80>=30,2,IF(G80>=10,1,0)) -> 1 | M80: =IF(H80="-",0,1) -> 0 | N80: =SUM(I80:M80) -> 2 | O80: =IF(N80<6,"일반",IF(N80<9,"우선",IF(N80>=9,"긴급"))) -> 일반 | P80: =RawData!Q76 -> -
