Workbook

Sheet RawData
B1: 시행사 구분 | C1: 권역구 구분
B2: 새서울철도㈜ | C2: 강남구
A4: 시행년도 | B4: 순번 | C4: 조사측선명 | D4: 손상구분번호 | E4: 침하(mm) | F4: 균열 | G4: 습윤 | H4: 노후도(년) | I4: 지반침하발생이력 | J4: 침하점수 | K4: 균열점수 | L4: 습윤점수 | M4: 노후도점수 | N4: 보수보강이력 | O4: 평가점수 | P4: 평가등급 | Q4: 조사자의견 | R4: 인접지번주소 | S4: 조사위치도 | T4: 부가정보1 | U4: 부가정보2
A5: 2026 | B5: 1 | C5: 강남대로 | D5: 26-강남구-01 | E5: 양호 | F5: 거북등 | G5: 양호 | H5: 4 | I5: - | J5: 0 | K5: 3 | L5: 0 | M5: 0 | N5: 0 | O5: 3 | P5: 일반 | Q5: - | R5: 신사동501 | T5: 신사역 #6번출구 앞도로(강남대로616)
A6: 2026 | B6: 2 | C6: 강남대로 | D6: 26-강남구-02 | E6: 양호 | F6: 거북등 | G6: 양호 | H6: 4 | I6: - | J6: 0 | K6: 3 | L6: 0 | M6: 0 | N6: 0 | O6: 3 | P6: 일반 | Q6: - | R6: 논현동1 | T6: 삼주빌딩 앞도로(강남대로606)
A7: 2026 | B7: 3 | C7: 강남대로 | D7: 26-강남구-03 | E7: 양호 | F7: 거북등 | G7: 양호 | H7: 4 | I7: - | J7: 0 | K7: 3 | L7: 0 | M7: 0 | N7: 0 | O7: 3 | P7: 일반 | Q7: - | R7: 논현동17-4 | T7: 보림빌딩 청기와타운_신사점 앞도로(강남대로598)
A8: 2026 | B8: 4 | C8: 강남대로 | D8: 26-강남구-04 | E8: 양호 | F8: 거북등 | G8: 양호 | H8: 4 | I8: - | J8: 0 | K8: 3 | L8: 0 | M8: 0 | N8: 0 | O8: 3 | P8: 일반 | Q8: - | R8: 논현동18-3 | T8: 제이빌딩 NHN벅스 앞도로(강남대로586)
A9: 2026 | B9: 5 | C9: 강남대로 | D9: 26-강남구-05 | E9: 양호 | F9: 거북등 | G9: 양호 | H9: 4 | I9: - | J9: 0 | K9: 3 | L9: 0 | M9: 0 | N9: 0 | O9: 3 | P9: 일반 | Q9: - | R9: 논현동19 | T9: 기아_강남영동지점 앞도로(강남대로580)
A10: 2026 | B10: 6 | C10: 강남대로 | D10: 26-강남구-06 | E10: 양호 | F10: 거북등 | G10: 양호 | H10: 4 | I10: - | J10: 0 | K10: 3 | L10: 0 | M10: 0 | N10: 0 | O10: 3 | P10: 일반 | Q10: - | R10: 논현동19-7 | T10: 전기공사공제조합회관 앞도로(강남대로574)
A11: 2026 | B11: 7 | C11: 강남대로 | D11: 26-강남구-07 | E11: 양호 | F11: 거북등 | G11: 양호 | H11: 4 | I11: - | J11: 0 | K11: 3 | L11: 0 | M11: 0 | N11: 0 | O11: 3 | P11: 일반 | Q11: - | R11: 논현동49 | T11: 선양빌딩 앞 도로(강남대로570)
A12: 2026 | B12: 8 | C12: 강남대로 | D12: 26-강남구-08 | E12: 양호 | F12: 거북등 | G12: 양호 | H12: 4 | I12: - | J12: 0 | K12: 3 | L12: 0 | M12: 0 | N12: 0 | O12: 3 | P12: 일반 | Q12: - | R12: 논현동49-4 | T12: 신영와코루빌딩 앞 도로(강남대로566)
A13: 2026 | B13: 9 | C13: 강남대로 | D13: 26-강남구-09 | E13: 양호 | F13: 거북등 | G13: 양호 | H13: 4 | I13: - | J13: 0 | K13: 3 | L13: 0 | M13: 0 | N13: 0 | O13: 3 | P13: 일반 | Q13: - | R13: 논현동49-17 | T13: 강남빌딩 앞 도로(감남대로562)
A14: 2026 | B14: 10 | C14: 강남대로 | D14: 26-강남구-10 | E14: 양호 | F14: 종균열 | G14: 양호 | H14: 4 | I14: - | J14: 0 | K14: 1 | L14: 0 | M14: 0 | N14: 0 | O14: 1 | P14: 일반 | Q14: - | R14: 논현동143 | T14: 신성빌딩 파리바게트 앞도로(강남대로532)
A15: 2026 | B15: 11 | C15: 강남대로 | D15: 26-강남구-11 | E15: 양호 | F15: 거북등 | G15: 양호 | H15: 4 | I15: - | J15: 0 | K15: 3 | L15: 0 | M15: 0 | N15: 0 | O15: 3 | P15: 일반 | Q15: - | R15: 논현동164 | T15: 영동빌딩 광성약국 앞도로(강남대로520)
A16: 2026 | B16: 12 | C16: 강남대로 | D16: 26-강남구-12 | E16: 양호 | F16: 거북등 | G16: 양호 | H16: 4 | I16: - | J16: 0 | K16: 3 | L16: 0 | M16: 0 | N16: 0 | O16: 3 | P16: 일반 | Q16: - | R16: 논현동164-11 | T16: 광명빌딩 정관장 앞도로(강남대로506)
... A28: 2026 | B28: 24 | C28: 강남대로 | D28: 26-강남구-24 | E28: 양호 | F28: 거북등 | G28: 양호 | H28: 4 | I28: - | J28: 0 | K28: 3 | L28: 0 | M28: 0 | N28: 0 | O28: 3 | P28: 일반 | Q28: - | R28: 역삼동816-2 | T28: 역삼빌딩 조앤조의원 앞 도로(강남대로420)
A29: 2025 | B29: 1 | C29: 강남대로 | D29: 25-강남구-1 | E29: 양호 | F29: 종균열 | G29: 양호 | H29: 2 | I29: - | J29: 0 | K29: 1 | L29: 0 | M29: 0 | N29: 0 | O29: 1 | P29: 일반 | R29: 신사동 501 | T29: 우리은행 앞 도로 (강남대로)
A30: 2025 | B30: 2 | C30: 강남대로 | D30: 25-강남구-2 | E30: 양호 | F30: - | G30: 양호 | H30: 2 | I30: - | J30: 0 | K30: 0 | L30: 0 | M30: 0 | N30: 0 | O30: 0 | P30: 일반 | Q30: 5cm미만 침하 | R30: 논현동 17 | T30: 신사역 환기구 앞 도로 (강남대로)
A31: 2025 | B31: 3 | C31: 강남대로 | D31: 25-강남구-3 | E31: 양호 | F31: 거북등 | G31: 양호 | H31: 2 | I31: - | J31: 0 | K31: 3 | L31: 0 | M31: 0 | N31: 0 | O31: 3 | P31: 일반 | R31: 논현동 17-4 | T31: 청기와타운 앞 도로 (강남대로)
A32: 2025 | B32: 4 | C32: 강남대로 | D32: 25-강남구-4 | E32: 양호 | F32: 거북등 | G32: 양호 | H32: 2 | I32: - | J32: 0 | K32: 3 | L32: 0 | M32: 0 | N32: 0 | O32: 3 | P32: 일반 | R32: 논현동 18-3 | T32: NHN벅스 앞 도로 (강남대로)
A33: 2025 | B33: 5 | C33: 강남대로 | D33: 25-강남구-5 | E33: 양호 | F33: 거북등 | G33: 양호 | H33: 2 | I33: - | J33: 0 | K33: 3 | L33: 0 | M33: 0 | N33: 0 | O33: 3 | P33: 일반 | R33: 논현동 19-2 | T33: 성현빌딩 앞 도로 (강남대로)
A34: 2025 | B34: 6 | C34: 강남대로 | D34: 25-강남구-6 | E34: 양호 | F34: 거북등 | G34: 양호 | H34: 2 | I34: - | J34: 0 | K34: 3 | L34: 0 | M34: 0 | N34: 0 | O34: 3 | P34: 일반 | R34: 논현동 49 | T34: CU편의점 앞 도로 (강남대로)
A35: 2025 | B35: 7 | C35: 강남대로 | D35: 25-강남구-7 | E35: 양호 | F35: 거북등 | G35: 양호 | H35: 2 | I35: - | J35: 0 | K35: 3 | L35: 0 | M35: 0 | N35: 0 | O35: 3 | P35: 일반 | R35: 논현동 49-17 | T35: 국제미디 논현점 앞 도로 (강남대로)
A36: 2025 | B36: 8 | C36: 강남대로 | D36: 25-강남구-8 | E36: 양호 | F36: 거북등 | G36: 양호 | H36: 2 | I36: - | J36: 0 | K36: 3 | L36: 0 | M36: 0 | N36: 0 | O36: 3 | P36: 일반 | R36: 논현동 50 | T36: 논현역#9번출구 앞 도로 (강남대로)
A37: 2025 | B37: 9 | C37: 강남대로 | D37: 25-강남구-9 | E37: 양호 | F37: - | G37: 양호 | H37: 2 | I37: - | J37: 0 | K37: 0 | L37: 0 | M37: 0 | N37: 0 | O37: 0 | P37: 일반 | Q37: 5cm미만 침하 | R37: 논현동 50-1 | T37: 논현역#9번출구 앞 도로 (강남대로)
A38: 2025 | B38: 10 | C38: 강남대로 | D38: 25-강남구-10 | E38: 양호 | F38: 거북등 | G38: 양호 | H38: 2 | I38: - | J38: 0 | K38: 3 | L38: 0 | M38: 0 | N38: 0 | O38: 3 | P38: 일반 | R38: 논현동 120 | T38: 논현역 교차로 도로 (강남대로)
A39: 2025 | B39: 11 | C39: 강남대로 | D39: 25-강남구-11 | E39: 양호 | F39: 거북등 | G39: 양호 | H39: 2 | I39: - | J39: 0 | K39: 3 | L39: 0 | M39: 0 | N39: 0 | O39: 3 | P39: 일반 | R39: 논현동 164 | T39: 할리스커피 앞 도로 (강남대로)
A40: 2025 | B40: 12 | C40: 강남대로 | D40: 25-강남구-12 | E40: 양호 | F40: 거북등 | G40: 양호 | H40: 2 | I40: - | J40: 0 | K40: 3 | L40: 0 | M40: 0 | N40: 0 | O40: 3 | P40: 일반 | R40: 논현동 164-4 | T40: 한국금거래소 강남논현점 앞 도로 (강남대로)
A41: 2025 | B41: 13 | C41: 강남대로 | D41: 25-강남구-13 | E41: 양호 | F41: 거북등 | G41: 양호 | H41: 2 | I41: - | J41: 0 | K41: 3 | L41: 0 | M41: 0 | N41: 0 | O41: 3 | P41: 일반 | R41: 논현동 165 | T41: 아웃백 앞 도로 (강남대로)
A42: 2025 | B42: 14 | C42: 강남대로 | D42: 25-강남구-14 | E42: 양호 | F42: - | G42: 양호 | H42: 2 | I42: - | J42: 0 | K42: 0 | L42: 0 | M42: 0 | N42: 0 | O42: 0 | P42: 일반 | Q42: 5cm미만 침하 | R42: 논현동 165-8 | T42: 나나성형 외과의원 앞 도로 (강남대로)
A43: 2025 | B43: 15 | C43: 강남대로 | D43: 25-강남구-15 | E43: 양호 | F43: 종균열 | G43: 양호 | H43: 2 | I43: - | J43: 0 | K43: 1 | L43: 0 | M43: 0 | N43: 0 | O43: 1 | P43: 일반 | R43: 논현동 199 | T43: 나나성형 외과의원 앞 횡단도로 (강남대로)
A44: 2025 | B44: 16 | C44: 강남대로 | D44: 25-강남구-16 | E44: 양호 | F44: 종균열 | G44: 양호 | H44: 2 | I44: - | J44: 0 | K44: 1 | L44: 0 | M44: 0 | N44: 0 | O44: 1 | P44: 일반 | R44: 논현동 200-7 | T44: 신논현역#3번출 앞 도로 (강남대로)
A45: 2025 | B45: 17 | C45: 강남대로 | D45: 25-강남구-17 | E45: 양호 | F45: 거북등 | G45: 양호 | H45: 2 | I45: - | J45: 0 | K45: 3 | L45: 0 | M45: 0 | N45: 0 | O45: 3 | P45: 일반 | R45: 역삼동 808 | T45: 아디다스 앞 도로 (강남대로)
A46: 2025 | B46: 18 | C46: 강남대로 | D46: 25-강남구-18 | E46: 양호 | F46: 거북등 | G46: 양호 | H46: 2 | I46: - | J46: 0 | K46: 3 | L46: 0 | M46: 0 | N46: 0 | O46: 3 | P46: 일반 | Q46: 5cm미만 침하 | R46: 역삼동 808-4 | T46: 신논현역 #5번출구 앞 도로 (강남대로)
A47: 2025 | B47: 19 | C47: 강남대로 | D47: 25-강남구-19 | E47: 양호 | F47: 거북등 | G47: 양호 | H47: 2 | I47: - | J47: 0 | K47: 3 | L47: 0 | M47: 0 | N47: 0 | O47: 3 | P47: 일반 | R47: 역삼동 809-12 | T47: 뮤즈의원 강남점 앞 도로 (강남대로)
A48: 2025 | B48: 20 | C48: 강남대로 | D48: 25-강남구-20 | E48: 양호 | F48: 종균열 | G48: 양호 | H48: 2 | I48: - | J48: 0 | K48: 1 | L48: 0 | M48: 0 | N48: 0 | O48: 1 | P48: 일반 | R48: 역삼동 814-5 | T48: 커피빈 앞 도로 (강남대로)
A49: 2025 | B49: 21 | C49: 강남대로 | D49: 25-강남구-21 | E49: 양호 | F49: - | G49: 양호 | H49: 2 | I49: - | J49: 0 | K49: 0 | L49: 0 | M49: 0 | N49: 0 | O49: 0 | P49: 일반 | Q49: 5cm미만 침하 | R49: 역삼동 814-6 | T49: CGV 앞 횡단보도 (강남대로)
A50: 2025 | B50: 22 | C50: 강남대로 | D50: 25-강남구-22 | E50: 양호 | F50: - | G50: 양호 | H50: 2 | I50: - | J50: 0 | K50: 0 | L50: 0 | M50: 0 | N50: 0 | O50: 0 | P50: 일반 | Q50: 5cm미만 침하 | R50: 역삼동 815 | T50: 강남e스퀘어 앞 도로 (강남대로)
A51: 2025 | B51: 23 | C51: 강남대로 | D51: 25-강남구-23 | E51: 양호 | F51: 거북등 | G51: 양호 | H51: 2 | I51: - | J51: 0 | K51: 3 | L51: 0 | M51: 0 | N51: 0 | O51: 3 | P51: 일반 | R51: 역삼동 815-2 | T51: ABC마트 앞 도로 (강남대로)
A52: 2025 | B52: 24 | C52: 강남대로 | D52: 25-강남구-24 | E52: 양호 | F52: 거북등 | G52: 양호 | H52: 2 | I52: - | J52: 0 | K52: 3 | L52: 0 | M52: 0 | N52: 0 | O52: 3 | P52: 일반 | R52: 역삼동 815-5 | T52: 진우빌딩 앞 도로 (강남대로)
...

Sheet V2
A2: ○ 육안조사 결과표
A4: 광역시도명 | C4: 서군구명 | E4: 대상시설명 | G4: 조사기간 | J4: 시설물관리자 | M4: 조사자
A5: 서울시 | C5: =RawData!C2 -> 강남구 | E5: 신분당선 | G5: 2026-03-17~2026-05-27 | J5: =RawData!B2 -> 새서울철도㈜ | M5: 기술참여자 명단 참조
A7: 순번 | B7: 조사측선명 | C7: 손상구분번호 | D7: 조사결과 | I7: 평가항목별 점수 | N7: 평가점수 | O7: 평가등급 | P7: 조사자 의견
D8: 침하(mm) | E8: 균열 | F8: 습윤 | G8: 노후도(년) | H8: 지반침하 발생 등의 이력1) (1년 이내) | I8: 침하 | J8: 균열 | K8: 습윤 | L8: 노후도 | M8: 보수보강이력
A9: =RIGHT(RawData!B5,2) -> 1 | B9: =RawData!C5 -> 강남대로 | C9: =RawData!D5 -> 26-강남구-01 | D9: =RawData!E5 -> 양호 | E9: =RawData!F5 -> 거북등 | F9: =RawData!G5 -> 양호 | G9: =RawData!H5 -> 4 | H9: =RawData!I5 -> - | I9: =IF(D9="양호",0,IF(D9="보통",3,IF(D9="불량",9))) -> 0 | J9: =IF(E9="거북등",3,IF(RIGHT(E9,2)="균열",1,IF(E9="-",0))) -> 3 | K9: =IF(F9="유출",9,IF(F9="습윤",1,IF(F9="양호",0,IF(F9="건조",0)))) -> 0 | L9: =IF(G9>=30,2,IF(G9>=10,1,0)) -> 0 | M9: =IF(H9="-",0,1) -> 0 | N9: =SUM(I9:M9) -> 3 | O9: =IF(N9<6,"일반",IF(N9<9,"우선",IF(N9>=9,"긴급"))) -> 일반 | P9: =RawData!Q5 -> -
A10: =RIGHT(RawData!B6,2) -> 2 | B10: =RawData!C6 -> 강남대로 | C10: =RawData!D6 -> 26-강남구-02 | D10: =RawData!E6 -> 양호 | E10: =RawData!F6 -> 거북등 | F10: =RawData!G6 -> 양호 | G10: =RawData!H6 -> 4 | H10: =RawData!I6 -> - | I10: =IF(D10="양호",0,IF(D10="보통",3,IF(D10="불량",9))) -> 0 | J10: =IF(E10="거북등",3,IF(RIGHT(E10,2)="균열",1,IF(E10="-",0))) -> 3 | K10: =IF(F10="유출",9,IF(F10="습윤",1,IF(F10="양호",0,IF(F10="건조",0)))) -> 0 | L10: =IF(G10>=30,2,IF(G10>=10,1,0)) -> 0 | M10: =IF(H10="-",0,1) -> 0 | N10: =SUM(I10:M10) -> 3 | O10: =IF(N10<6,"일반",IF(N10<9,"우선",IF(N10>=9,"긴급"))) -> 일반 | P10: =RawData!Q6 -> -
A11: =RIGHT(RawData!B7,2) -> 3 | B11: =RawData!C7 -> 강남대로 | C11: =RawData!D7 -> 26-강남구-03 | D11: =RawData!E7 -> 양호 | E11: =RawData!F7 -> 거북등 | F11: =RawData!G7 -> 양호 | G11: =RawData!H7 -> 4 | H11: =RawData!I7 -> - | I11: =IF(D11="양호",0,IF(D11="보통",3,IF(D11="불량",9))) -> 0 | J11: =IF(E11="거북등",3,IF(RIGHT(E11,2)="균열",1,IF(E11="-",0))) -> 3 | K11: =IF(F11="유출",9,IF(F11="습윤",1,IF(F11="양호",0,IF(F11="건조",0)))) -> 0 | L11: =IF(G11>=30,2,IF(G11>=10,1,0)) -> 0 | M11: =IF(H11="-",0,1) -> 0 | N11: =SUM(I11:M11) -> 3 | O11: =IF(N11<6,"일반",IF(N11<9,"우선",IF(N11>=9,"긴급"))) -> 일반 | P11: =RawData!Q7 -> -
A12: =RIGHT(RawData!B8,2) -> 4 | B12: =RawData!C8 -> 강남대로 | C12: =RawData!D8 -> 26-강남구-04 | D12: =RawData!E8 -> 양호 | E12: =RawData!F8 -> 거북등 | F12: =RawData!G8 -> 양호 | G12: =RawData!H8 -> 4 | H12: =RawData!I8 -> - | I12: =IF(D12="양호",0,IF(D12="보통",3,IF(D12="불량",9))) -> 0 | J12: =IF(E12="거북등",3,IF(RIGHT(E12,2)="균열",1,IF(E12="-",0))) -> 3 | K12: =IF(F12="유출",9,IF(F12="습윤",1,IF(F12="양호",0,IF(F12="건조",0)))) -> 0 | L12: =IF(G12>=30,2,IF(G12>=10,1,0)) -> 0 | M12: =IF(H12="-",0,1) -> 0 | N12: =SUM(I12:M12) -> 3 | O12: =IF(N12<6,"일반",IF(N12<9,"우선",IF(N12>=9,"긴급"))) -> 일반 | P12: =RawData!Q8 -> -
A13: =RIGHT(RawData!B9,2) -> 5 | B13: =RawData!C9 -> 강남대로 | C13: =RawData!D9 -> 26-강남구-05 | D13: =RawData!E9 -> 양호 | E13: =RawData!F9 -> 거북등 | F13: =RawData!G9 -> 양호 | G13: =RawData!H9 -> 4 | H13: =RawData!I9 -> - | I13: =IF(D13="양호",0,IF(D13="보통",3,IF(D13="불량",9))) -> 0 | J13: =IF(E13="거북등",3,IF(RIGHT(E13,2)="균열",1,IF(E13="-",0))) -> 3 | K13: =IF(F13="유출",9,IF(F13="습윤",1,IF(F13="양호",0,IF(F13="건조",0)))) -> 0 | L13: =IF(G13>=30,2,IF(G13>=10,1,0)) -> 0 | M13: =IF(H13="-",0,1) -> 0 | N13: =SUM(I13:M13) -> 3 | O13: =IF(N13<6,"일반",IF(N13<9,"우선",IF(N13>=9,"긴급"))) -> 일반 | P13: =RawData!Q9 -> -
A14: =RIGHT(RawData!B10,2) -> 6 | B14: =RawData!C10 -> 강남대로 | C14: =RawData!D10 -> 26-강남구-06 | D14: =RawData!E10 -> 양호 | E14: =RawData!F10 -> 거북등 | F14: =RawData!G10 -> 양호 | G14: =RawData!H10 -> 4 | H14: =RawData!I10 -> - | I14: =IF(D14="양호",0,IF(D14="보통",3,IF(D14="불량",9))) -> 0 | J14: =IF(E14="거북등",3,IF(RIGHT(E14,2)="균열",1,IF(E14="-",0))) -> 3 | K14: =IF(F14="유출",9,IF(F14="습윤",1,IF(F14="양호",0,IF(F14="건조",0)))) -> 0 | L14: =IF(G14>=30,2,IF(G14>=10,1,0)) -> 0 | M14: =IF(H14="-",0,1) -> 0 | N14: =SUM(I14:M14) -> 3 | O14: =IF(N14<6,"일반",IF(N14<9,"우선",IF(N14>=9,"긴급"))) -> 일반 | P14: =RawData!Q10 -> -
A15: =RIGHT(RawData!B11,2) -> 7 | B15: =RawData!C11 -> 강남대로 | C15: =RawData!D11 -> 26-강남구-07 | D15: =RawData!E11 -> 양호 | E15: =RawData!F11 -> 거북등 | F15: =RawData!G11 -> 양호 | G15: =RawData!H11 -> 4 | H15: =RawData!I11 -> - | I15: =IF(D15="양호",0,IF(D15="보통",3,IF(D15="불량",9))) -> 0 | J15: =IF(E15="거북등",3,IF(RIGHT(E15,2)="균열",1,IF(E15="-",0))) -> 3 | K15: =IF(F15="유출",9,IF(F15="습윤",1,IF(F15="양호",0,IF(F15="건조",0)))) -> 0 | L15: =IF(G15>=30,2,IF(G15>=10,1,0)) -> 0 | M15: =IF(H15="-",0,1) -> 0 | N15: =SUM(I15:M15) -> 3 | O15: =IF(N15<6,"일반",IF(N15<9,"우선",IF(N15>=9,"긴급"))) -> 일반 | P15: =RawData!Q11 -> -
A16: =RIGHT(RawData!B12,2) -> 8 | B16: =RawData!C12 -> 강남대로 | C16: =RawData!D12 -> 26-강남구-08 | D16: =RawData!E12 -> 양호 | E16: =RawData!F12 -> 거북등 | F16: =RawData!G12 -> 양호 | G16: =RawData!H12 -> 4 | H16: =RawData!I12 -> - | I16: =IF(D16="양호",0,IF(D16="보통",3,IF(D16="불량",9))) -> 0 | J16: =IF(E16="거북등",3,IF(RIGHT(E16,2)="균열",1,IF(E16="-",0))) -> 3 | K16: =IF(F16="유출",9,IF(F16="습윤",1,IF(F16="양호",0,IF(F16="건조",0)))) -> 0 | L16: =IF(G16>=30,2,IF(G16>=10,1,0)) -> 0 | M16: =IF(H16="-",0,1) -> 0 | N16: =SUM(I16:M16) -> 3 | O16: =IF(N16<6,"일반",IF(N16<9,"우선",IF(N16>=9,"긴급"))) -> 일반 | P16: =RawData!Q12 -> -
A17: =RIGHT(RawData!B13,2) -> 9 | B17: =RawData!C13 -> 강남대로 | C17: =RawData!D13 -> 26-강남구-09 | D17: =RawData!E13 -> 양호 | E17: =RawData!F13 -> 거북등 | F17: =RawData!G13 -> 양호 | G17: =RawData!H13 -> 4 | H17: =RawData!I13 -> - | I17: =IF(D17="양호",0,IF(D17="보통",3,IF(D17="불량",9))) -> 0 | J17: =IF(E17="거북등",3,IF(RIGHT(E17,2)="균열",1,IF(E17="-",0))) -> 3 | K17: =IF(F17="유출",9,IF(F17="습윤",1,IF(F17="양호",0,IF(F17="건조",0)))) -> 0 | L17: =IF(G17>=30,2,IF(G17>=10,1,0)) -> 0 | M17: =IF(H17="-",0,1) -> 0 | N17: =SUM(I17:M17) -> 3 | O17: =IF(N17<6,"일반",IF(N17<9,"우선",IF(N17>=9,"긴급"))) -> 일반 | P17: =RawData!Q13 -> -
A18: =RIGHT(RawData!B14,2) -> 10 | B18: =RawData!C14 -> 강남대로 | C18: =RawData!D14 -> 26-강남구-10 | D18: =RawData!E14 -> 양호 | E18: =RawData!F14 -> 종균열 | F18: =RawData!G14 -> 양호 | G18: =RawData!H14 -> 4 | H18: =RawData!I14 -> - | I18: =IF(D18="양호",0,IF(D18="보통",3,IF(D18="불량",9))) -> 0 | J18: =IF(E18="거북등",3,IF(RIGHT(E18,2)="균열",1,IF(E18="-",0))) -> 1 | K18: =IF(F18="유출",9,IF(F18="습윤",1,IF(F18="양호",0,IF(F18="건조",0)))) -> 0 | L18: =IF(G18>=30,2,IF(G18>=10,1,0)) -> 0 | M18: =IF(H18="-",0,1) -> 0 | N18: =SUM(I18:M18) -> 1 | O18: =IF(N18<6,"일반",IF(N18<9,"우선",IF(N18>=9,"긴급"))) -> 일반 | P18: =RawData!Q14 -> -
A19: =RIGHT(RawData!B15,2) -> 11 | B19: =RawData!C15 -> 강남대로 | C19: =RawData!D15 -> 26-강남구-11 | D19: =RawData!E15 -> 양호 | E19: =RawData!F15 -> 거북등 | F19: =RawData!G15 -> 양호 | G19: =RawData!H15 -> 4 | H19: =RawData!I15 -> - | I19: =IF(D19="양호",0,IF(D19="보통",3,IF(D19="불량",9))) -> 0 | J19: =IF(E19="거북등",3,IF(RIGHT(E19,2)="균열",1,IF(E19="-",0))) -> 3 | K19: =IF(F19="유출",9,IF(F19="습윤",1,IF(F19="양호",0,IF(F19="건조",0)))) -> 0 | L19: =IF(G19>=30,2,IF(G19>=10,1,0)) -> 0 | M19: =IF(H19="-",0,1) -> 0 | N19: =SUM(I19:M19) -> 3 | O19: =IF(N19<6,"일반",IF(N19<9,"우선",IF(N19>=9,"긴급"))) -> 일반 | P19: =RawData!Q15 -> -
A20: =RIGHT(RawData!B16,2) -> 12 | B20: =RawData!C16 -> 강남대로 | C20: =RawData!D16 -> 26-강남구-12 | D20: =RawData!E16 -> 양호 | E20: =RawData!F16 -> 거북등 | F20: =RawData!G16 -> 양호 | G20: =RawData!H16 -> 4 | H20: =RawData!I16 -> - | I20: =IF(D20="양호",0,IF(D20="보통",3,IF(D20="불량",9))) -> 0 | J20: =IF(E20="거북등",3,IF(RIGHT(E20,2)="균열",1,IF(E20="-",0))) -> 3 | K20: =IF(F20="유출",9,IF(F20="습윤",1,IF(F20="양호",0,IF(F20="건조",0)))) -> 0 | L20: =IF(G20>=30,2,IF(G20>=10,1,0)) -> 0 | M20: =IF(H20="-",0,1) -> 0 | N20: =SUM(I20:M20) -> 3 | O20: =IF(N20<6,"일반",IF(N20<9,"우선",IF(N20>=9,"긴급"))) -> 일반 | P20: =RawData!Q16 -> -
... A32: =RIGHT(RawData!B28,2) -> 24 | B32: =RawData!C28 -> 강남대로 | C32: =RawData!D28 -> 26-강남구-24 | D32: =RawData!E28 -> 양호 | E32: =RawData!F28 -> 거북등 | F32: =RawData!G28 -> 양호 | G32: =RawData!H28 -> 4 | H32: =RawData!I28 -> - | I32: =IF(D32="양호",0,IF(D32="보통",3,IF(D32="불량",9))) -> 0 | J32: =IF(E32="거북등",3,IF(RIGHT(E32,2)="균열",1,IF(E32="-",0))) -> 3 | K32: =IF(F32="유출",9,IF(F32="습윤",1,IF(F32="양호",0,IF(F32="건조",0)))) -> 0 | L32: =IF(G32>=30,2,IF(G32>=10,1,0)) -> 0 | M32: =IF(H32="-",0,1) -> 0 | N32: =SUM(I32:M32) -> 3 | O32: =IF(N32<6,"일반",IF(N32<9,"우선",IF(N32>=9,"긴급"))) -> 일반 | P32: =RawData!Q28 -> -
